Workbook

Sheet Spearmans2
A1: rowname | B1: rowname minus ws | C1: Name | D1: Category | E1: Subcategory | F1: Metric description | G1: colname | H1: rowname minus ws | I1: Name | J1: Category | K1: Description | L1: cor
A2: AGKFFACTWS | B2: =IF(RIGHT(A2,2)="WS", LEFT(A2,LEN(A2)-2),A2) -> AGKFFACT | C2: =INDEX(Active!J:J, MATCH(Spearmans2!B2, Active!F:F,0),1) -> Ag Soil Erodibility Kf Factor | D2: =INDEX(Active!B:B, MATCH(Spearmans2!B2, Active!F:F,0),1) -> Anthropogenic | E2: =INDEX(Active!D:D, MATCH(Spearmans2!B2, Active!F:F,0),1) -> Agriculture | F2: =INDEX(Active!K:K, MATCH(Spearmans2!B2, Active!F:F,0),1) -> Mean of STATSGO Kffactor raster on agricultural land (NLCD 2006) within AOI. The Universal Soil Loss Equation (USLE) and represents a relative index of susceptibility of bare, cultivated soil to particle detachment and transport by rainfall | G2: CBNFWS | H2: =IF(RIGHT(G2,2)="WS", LEFT(G2,LEN(G2)-2),G2) -> CBNF | I2: =INDEX(Active!J:J, MATCH(Spearmans2!H2, Active!F:F,0),1) -> Cultivated Biological Nitrogen Fixation Mean Rate | J2: =INDEX(Active!B:B, MATCH(Spearmans2!H2, Active!F:F,0),1) -> Anthropogenic | K2: =INDEX(Active!K:K, MATCH(Spearmans2!H2, Active!F:F,0),1) -> Mean rate of biological nitrogen fixation from the cultivation of crops in kg N/ha/yr, within AOI | L2: 0.98243648
A3: AGKFFACTWS | B3: =IF(RIGHT(A3,2)="WS", LEFT(A3,LEN(A3)-2),A3) -> AGKFFACT | C3: =INDEX(Active!J:J, MATCH(Spearmans2!B3, Active!F:F,0),1) -> Ag Soil Erodibility Kf Factor | D3: =INDEX(Active!B:B, MATCH(Spearmans2!B3, Active!F:F,0),1) -> Anthropogenic | E3: =INDEX(Active!D:D, MATCH(Spearmans2!B3, Active!F:F,0),1) -> Agriculture | F3: =INDEX(Active!K:K, MATCH(Spearmans2!B3, Active!F:F,0),1) -> Mean of STATSGO Kffactor raster on agricultural land (NLCD 2006) within AOI. The Universal Soil Loss Equation (USLE) and represents a relative index of susceptibility of bare, cultivated soil to particle detachment and transport by rainfall | G3: FERTWS | H3: =IF(RIGHT(G3,2)="WS", LEFT(G3,LEN(G3)-2),G3) -> FERT | I3: =INDEX(Active!J:J, MATCH(Spearmans2!H3, Active!F:F,0),1) -> Synthetic Nitrogen Fertilizer Application Mean Rate | J3: =INDEX(Active!B:B, MATCH(Spearmans2!H3, Active!F:F,0),1) -> Anthropogenic | K3: =INDEX(Active!K:K, MATCH(Spearmans2!H3, Active!F:F,0),1) -> Mean rate of synthetic nitrogen fertilizer application to agricultural land in kg N/ha/yr, within the AOI | L3: 0.98664057
A4: AGKFFACTWS | B4: =IF(RIGHT(A4,2)="WS", LEFT(A4,LEN(A4)-2),A4) -> AGKFFACT | C4: =INDEX(Active!J:J, MATCH(Spearmans2!B4, Active!F:F,0),1) -> Ag Soil Erodibility Kf Factor | D4: =INDEX(Active!B:B, MATCH(Spearmans2!B4, Active!F:F,0),1) -> Anthropogenic | E4: =INDEX(Active!D:D, MATCH(Spearmans2!B4, Active!F:F,0),1) -> Agriculture | F4: =INDEX(Active!K:K, MATCH(Spearmans2!B4, Active!F:F,0),1) -> Mean of STATSGO Kffactor raster on agricultural land (NLCD 2006) within AOI. The Universal Soil Loss Equation (USLE) and represents a relative index of susceptibility of bare, cultivated soil to particle detachment and transport by rainfall | G4: MANUREWS | H4: =IF(RIGHT(G4,2)="WS", LEFT(G4,LEN(G4)-2),G4) -> MANURE | I4: =INDEX(Active!J:J, MATCH(Spearmans2!H4, Active!F:F,0),1) -> Mean Manure Application Rate | J4: =INDEX(Active!B:B, MATCH(Spearmans2!H4, Active!F:F,0),1) -> Anthropogenic | K4: =INDEX(Active!K:K, MATCH(Spearmans2!H4, Active!F:F,0),1) -> Mean rate of manure application to agricultural land from confined animal feeding operations in kg N/ha/yr, within AOI | L4: 0.88720799
A5: AGKFFACTWS | B5: =IF(RIGHT(A5,2)="WS", LEFT(A5,LEN(A5)-2),A5) -> AGKFFACT | C5: =INDEX(Active!J:J, MATCH(Spearmans2!B5, Active!F:F,0),1) -> Ag Soil Erodibility Kf Factor | D5: =INDEX(Active!B:B, MATCH(Spearmans2!B5, Active!F:F,0),1) -> Anthropogenic | E5: =INDEX(Active!D:D, MATCH(Spearmans2!B5, Active!F:F,0),1) -> Agriculture | F5: =INDEX(Active!K:K, MATCH(Spearmans2!B5, Active!F:F,0),1) -> Mean of STATSGO Kffactor raster on agricultural land (NLCD 2006) within AOI. The Universal Soil Loss Equation (USLE) and represents a relative index of susceptibility of bare, cultivated soil to particle detachment and transport by rainfall | G5: WATERINPUTWS | H5: =IF(RIGHT(G5,2)="WS", LEFT(G5,LEN(G5)-2),G5) -> WATERINPUT | I5: =INDEX(Active!J:J, MATCH(Spearmans2!H5, Active!F:F,0),1) -> Water Input | J5: =INDEX(Active!B:B, MATCH(Spearmans2!H5, Active!F:F,0),1) -> Anthropogenic | K5: =INDEX(Active!K:K, MATCH(Spearmans2!H5, Active!F:F,0),1) -> Water Input (km2/cm): Ratio of the total area of irrigated land to precipitation within AOI | L5: 0.92320942
A6: AGKFFACTWS | B6: =IF(RIGHT(A6,2)="WS", LEFT(A6,LEN(A6)-2),A6) -> AGKFFACT | C6: =INDEX(Active!J:J, MATCH(Spearmans2!B6, Active!F:F,0),1) -> Ag Soil Erodibility Kf Factor | D6: =INDEX(Active!B:B, MATCH(Spearmans2!B6, Active!F:F,0),1) -> Anthropogenic | E6: =INDEX(Active!D:D, MATCH(Spearmans2!B6, Active!F:F,0),1) -> Agriculture | F6: =INDEX(Active!K:K, MATCH(Spearmans2!B6, Active!F:F,0),1) -> Mean of STATSGO Kffactor raster on agricultural land (NLCD 2006) within AOI. The Universal Soil Loss Equation (USLE) and represents a relative index of susceptibility of bare, cultivated soil to particle detachment and transport by rainfall | G6: WDRW_LDWS | H6: =IF(RIGHT(G6,2)="WS", LEFT(G6,LEN(G6)-2),G6) -> WDRW_LD | I6: =INDEX(Active!J:J, MATCH(Spearmans2!H6, Active!F:F,0),1) -> Agricultural Fresh Surface-Water Withdraw | J6: =INDEX(Active!B:B, MATCH(Spearmans2!H6, Active!F:F,0),1) -> Anthropogenic | K6: =INDEX(Active!K:K, MATCH(Spearmans2!H6, Active!F:F,0),1) -> Total fresh surface-water withdrawals in agricultural land per AOI area (L/day) | L6: 0.93960966
A7: AL2O3WS | B7: =IF(RIGHT(A7,2)="WS", LEFT(A7,LEN(A7)-2),A7) -> AL2O3 | C7: =INDEX(Active!J:J, MATCH(Spearmans2!B7, Active!F:F,0),1) -> Mean Lithological Aluminum Oxide | D7: =INDEX(Active!B:B, MATCH(Spearmans2!B7, Active!F:F,0),1) -> Natural | E7: =INDEX(Active!D:D, MATCH(Spearmans2!B7, Active!F:F,0),1) -> Lithology | F7: =INDEX(Active!K:K, MATCH(Spearmans2!B7, Active!F:F,0),1) -> Mean % of lithological aluminum oxide (Al2O3) content in surface or near surface geology within AOI | G7: CAOWS | H7: =IF(RIGHT(G7,2)="WS", LEFT(G7,LEN(G7)-2),G7) -> CAO | I7: =INDEX(Active!J:J, MATCH(Spearmans2!H7, Active!F:F,0),1) -> Mean Lithological Calcium Oxide | J7: =INDEX(Active!B:B, MATCH(Spearmans2!H7, Active!F:F,0),1) -> Natural | K7: =INDEX(Active!K:K, MATCH(Spearmans2!H7, Active!F:F,0),1) -> Mean % of lithological calcium oxide (CaO) content in surface or near surface geology within AOI | L7: 0.84628043
A8: AL2O3WS | B8: =IF(RIGHT(A8,2)="WS", LEFT(A8,LEN(A8)-2),A8) -> AL2O3 | C8: =INDEX(Active!J:J, MATCH(Spearmans2!B8, Active!F:F,0),1) -> Mean Lithological Aluminum Oxide | D8: =INDEX(Active!B:B, MATCH(Spearmans2!B8, Active!F:F,0),1) -> Natural | E8: =INDEX(Active!D:D, MATCH(Spearmans2!B8, Active!F:F,0),1) -> Lithology | F8: =INDEX(Active!K:K, MATCH(Spearmans2!B8, Active!F:F,0),1) -> Mean % of lithological aluminum oxide (Al2O3) content in surface or near surface geology within AOI | G8: NA2OWS | H8: =IF(RIGHT(G8,2)="WS", LEFT(G8,LEN(G8)-2),G8) -> NA2O | I8: =INDEX(Active!J:J, MATCH(Spearmans2!H8, Active!F:F,0),1) -> Mean Lithological Sodium Oxide | J8: =INDEX(Active!B:B, MATCH(Spearmans2!H8, Active!F:F,0),1) -> Natural | K8: =INDEX(Active!K:K, MATCH(Spearmans2!H8, Active!F:F,0),1) -> Mean % of lithological sodium oxide (Na2O) content in surface or near surface geology within AOI | L8: 0.94939989
A9: AL2O3WS | B9: =IF(RIGHT(A9,2)="WS", LEFT(A9,LEN(A9)-2),A9) -> AL2O3 | C9: =INDEX(Active!J:J, MATCH(Spearmans2!B9, Active!F:F,0),1) -> Mean Lithological Aluminum Oxide | D9: =INDEX(Active!B:B, MATCH(Spearmans2!B9, Active!F:F,0),1) -> Natural | E9: =INDEX(Active!D:D, MATCH(Spearmans2!B9, Active!F:F,0),1) -> Lithology | F9: =INDEX(Active!K:K, MATCH(Spearmans2!B9, Active!F:F,0),1) -> Mean % of lithological aluminum oxide (Al2O3) content in surface or near surface geology within AOI | G9: P2O5WS | H9: =IF(RIGHT(G9,2)="WS", LEFT(G9,LEN(G9)-2),G9) -> P2O5 | I9: =INDEX(Active!J:J, MATCH(Spearmans2!H9, Active!F:F,0),1) -> Mean Lithological Phosphorous Oxide | J9: =INDEX(Active!B:B, MATCH(Spearmans2!H9, Active!F:F,0),1) -> Natural | K9: =INDEX(Active!K:K, MATCH(Spearmans2!H9, Active!F:F,0),1) -> Mean % of lithological phosphorous oxide (P2O5) content in surface or near surface geology within AOI | L9: 0.88677451
A10: BANKFULLDEPTH | B10: =IF(RIGHT(A10,2)="WS", LEFT(A10,LEN(A10)-2),A10) -> BANKFULLDEPTH | C10: =INDEX(Active!J:J, MATCH(Spearmans2!B10, Active!F:F,0),1) -> Predicted Bankfull Depth | D10: =INDEX(Active!B:B, MATCH(Spearmans2!B10, Active!F:F,0),1) -> Natural | E10: =INDEX(Active!D:D, MATCH(Spearmans2!B10, Active!F:F,0),1) -> Other | F10: =INDEX(Active!K:K, MATCH(Spearmans2!B10, Active!F:F,0),1) -> Predicted bankfull depth: thalweg depth plus bankfull height, which is the height from the water surface to the bankfull stage | G10: BANKFULLWIDTH | H10: =IF(RIGHT(G10,2)="WS", LEFT(G10,LEN(G10)-2),G10) -> BANKFULLWIDTH | I10: =INDEX(Active!J:J, MATCH(Spearmans2!H10, Active!F:F,0),1) -> Predicted Bankfull Width | J10: =INDEX(Active!B:B, MATCH(Spearmans2!H10, Active!F:F,0),1) -> Natural | K10: =INDEX(Active!K:K, MATCH(Spearmans2!H10, Active!F:F,0),1) -> Predicted bankfull width: distance from left to right bank at bankfull stage where the potential water height would spill outside of the channel and into the floodplain | L10: 0.93596905
A11: BANKFULLDEPTH | B11: =IF(RIGHT(A11,2)="WS", LEFT(A11,LEN(A11)-2),A11) -> BANKFULLDEPTH | C11: =INDEX(Active!J:J, MATCH(Spearmans2!B11, Active!F:F,0),1) -> Predicted Bankfull Depth | D11: =INDEX(Active!B:B, MATCH(Spearmans2!B11, Active!F:F,0),1) -> Natural | E11: =INDEX(Active!D:D, MATCH(Spearmans2!B11, Active!F:F,0),1) -> Other | F11: =INDEX(Active!K:K, MATCH(Spearmans2!B11, Active!F:F,0),1) -> Predicted bankfull depth: thalweg depth plus bankfull height, which is the height from the water surface to the bankfull stage | G11: NSURPWS | H11: =IF(RIGHT(G11,2)="WS", LEFT(G11,LEN(G11)-2),G11) -> NSURP | I11: =INDEX(Active!J:J, MATCH(Spearmans2!H11, Active!F:F,0),1) -> Nitrogen Surplus | J11: =INDEX(Active!B:B, MATCH(Spearmans2!H11, Active!F:F,0),1) -> Anthropogenic | K11: =INDEX(Active!K:K, MATCH(Spearmans2!H11, Active!F:F,0),1) -> Nitrogen Surplus (kg N / yr) per AOI - excluding biological N Fixation | L11: 0.81101431
A12: BANKFULLDEPTH | B12: =IF(RIGHT(A12,2)="WS", LEFT(A12,LEN(A12)-2),A12) -> BANKFULLDEPTH | C12: =INDEX(Active!J:J, MATCH(Spearmans2!B12, Active!F:F,0),1) -> Predicted Bankfull Depth | D12: =INDEX(Active!B:B, MATCH(Spearmans2!B12, Active!F:F,0),1) -> Natural | E12: =INDEX(Active!D:D, MATCH(Spearmans2!B12, Active!F:F,0),1) -> Other | F12: =INDEX(Active!K:K, MATCH(Spearmans2!B12, Active!F:F,0),1) -> Predicted bankfull depth: thalweg depth plus bankfull height, which is the height from the water surface to the bankfull stage | G12: THALWEGDEPTH | H12: =IF(RIGHT(G12,2)="WS", LEFT(G12,LEN(G12)-2),G12) -> THALWEGDEPTH | I12: =INDEX(Active!J:J, MATCH(Spearmans2!H12, Active!F:F,0),1) -> #N/A | J12: =INDEX(Active!B:B, MATCH(Spearmans2!H12, Active!F:F,0),1) -> #N/A | K12: =INDEX(Active!K:K, MATCH(Spearmans2!H12, Active!F:F,0),1) -> #N/A | L12: 0.92650655
A13: BANKFULLDEPTH | B13: =IF(RIGHT(A13,2)="WS", LEFT(A13,LEN(A13)-2),A13) -> BANKFULLDEPTH | C13: =INDEX(Active!J:J, MATCH(Spearmans2!B13, Active!F:F,0),1) -> Predicted Bankfull Depth | D13: =INDEX(Active!B:B, MATCH(Spearmans2!B13, Active!F:F,0),1) -> Natural | E13: =INDEX(Active!D:D, MATCH(Spearmans2!B13, Active!F:F,0),1) -> Other | F13: =INDEX(Active!K:K, MATCH(Spearmans2!B13, Active!F:F,0),1) -> Predicted bankfull depth: thalweg depth plus bankfull height, which is the height from the water surface to the bankfull stage | G13: WETTEDWIDTH | H13: =IF(RIGHT(G13,2)="WS", LEFT(G13,LEN(G13)-2),G13) -> WETTEDWIDTH | I13: =INDEX(Active!J:J, MATCH(Spearmans2!H13, Active!F:F,0),1) -> Predicted Wetted Width | J13: =INDEX(Active!B:B, MATCH(Spearmans2!H13, Active!F:F,0),1) -> Natural | K13: =INDEX(Active!K:K, MATCH(Spearmans2!H13, Active!F:F,0),1) -> Predicted wetted width: distance of the waters edge from left to right bank | L13: 0.9327908
... A321: WWTPMINORDENSWS | B321: =IF(RIGHT(A321,2)="WS", LEFT(A321,LEN(A321)-2),A321) -> WWTPMINORDENS | C321: =INDEX(Active!J:J, MATCH(Spearmans2!B321, Active!F:F,0),1) -> Minor Wastewater Treatment Density | D321: =INDEX(Active!B:B, MATCH(Spearmans2!B321, Active!F:F,0),1) -> Anthropogenic | E321: =INDEX(Active!D:D, MATCH(Spearmans2!B321, Active!F:F,0),1) -> Urban | F321: =INDEX(Active!K:K, MATCH(Spearmans2!B321, Active!F:F,0),1) -> Density (number/ km2) of minor wastewater treatment plants per AOI | G321: WWTPALLDENSWS | H321: =IF(RIGHT(G321,2)="WS", LEFT(G321,LEN(G321)-2),G321) -> WWTPALLDENS | I321: =INDEX(Active!J:J, MATCH(Spearmans2!H321, Active!F:F,0),1) -> All Wastewater Treatment Density | J321: =INDEX(Active!B:B, MATCH(Spearmans2!H321, Active!F:F,0),1) -> Anthropogenic | K321: =INDEX(Active!K:K, MATCH(Spearmans2!H321, Active!F:F,0),1) -> Density (number/ km2) of all wastewater treatment plants per AOI | L321: 0.99999701

Sheet Active
A1: Use? | B1: Category | C1: Subcategory_SC | D1: Subcategory | E1: Metric | F1: Metric_Query | G1: missing_from_pull | H1: AOI | I1: Year | J1: Short_Name | K1: Metric_Description | L1: Units | M1: Source | N1: Dataset
A2: y | B2: Anthropogenic | C2: Soils | D2: Agriculture | E2: agkffact[AOI] | F2: agkffact | H2: Cat, Ws | J2: Ag Soil Erodibility Kf Factor | K2: Mean of STATSGO Kffactor raster on agricultural land (NLCD 2006) within AOI. The Universal Soil Loss Equation (USLE) and represents a relative index of susceptibility of bare, cultivated soil to particle detachment and transport by rainfall | L2: Unitless | M2: Penn State Soil Info | N2: STATSGO Soils
A3: y | B3: Natural | C3: Natural | D3: Lithology | E3: al2o3[AOI] | F3: al2o3 | H3: Cat, Ws | J3: Mean Lithological Aluminum Oxide | K3: Mean % of lithological aluminum oxide (Al2O3) content in surface or near surface geology within AOI | L3: Percent | M3: USGS Sciencebase | N3: USGS Geochemistry
A4: n | B4: Base | C4: Base | D4: Area | E4: areasqkm[AOI] | F4: areasqkm | H4: Ws | J4: Watershed Area Square Kilometers | K4: Watershed area (square km) | L4: Square Kilometers | M4: NHDPlusV2 | N4: All
A5: y | B5: Natural | C5: Natural | D5: Other | E5: bankfulldepth | F5: bankfulldepth | H5: Other | J5: Predicted Bankfull Depth | K5: Predicted bankfull depth: thalweg depth plus bankfull height, which is the height from the water surface to the bankfull stage | L5: Meters | M5: Doyle et al. 2023 | N5: Predicted Channel Widths Depths
A6: y | B6: Natural | C6: Natural | D6: Other | E6: bankfullwidth | F6: bankfullwidth | H6: Other | J6: Predicted Bankfull Width | K6: Predicted bankfull width: distance from left to right bank at bankfull stage where the potential water height would spill outside of the channel and into the floodplain | L6: Meters | M6: Doyle et al. 2023 | N6: Predicted Channel Widths Depths
A7: y | B7: Natural | C7: Climate | D7: Flow | E7: bfi[AOI] | F7: bfi | H7: Cat, Ws | J7: Base Flow Index | K7: Base flow is the component of streamflow that can be attributed to ground-water discharge into streams. The BFI is the ratio of base flow to total flow, expressed as a percentage, within AOI | L7: Percent | M7: USGS Water Mission Area | N7: Base Flow Index
A8: y | B8: Anthropogenic | C8: Anthropogenic | D8: Agriculture | E8: canaldens[AOI] | F8: canaldens | H8: Cat, Ws | J8: Canal Density | K8: Density of NHDPlus line features classified as canal, ditch, or pipeline within the AOI (km/ square km) | L8: Kilometer/Square Kilometer | M8: Falcone et al. 2010 | N8: Canal Density
A9: y | B9: Natural | C9: Natural | D9: Lithology | E9: cao[AOI] | F9: cao | H9: Cat, Ws | J9: Mean Lithological Calcium Oxide | K9: Mean % of lithological calcium oxide (CaO) content in surface or near surface geology within AOI | L9: Percent | M9: USGS Sciencebase | N9: USGS Geochemistry
A10: n | B10: Base | C10: Base | D10: Area | E10: catareasqkm[AOI] | F10: catareasqkm | H10: Cat | J10: Catchment Area Square Kilometers | K10: Area of local NHDPlus AOI (square km) | L10: Square Kilometers | M10: NHDPlusV2 | N10: All
A11: n | B11: Base | C11: Base | D11: Area | E11: catareasqkmrp100[AOI] | F11: catareasqkmrp100 | H11: Cat, CatRp100 | J11: AOI Area Square Kilometers Riparian 100 Meters | K11: Area of local NHDPlus AOIs (square km) within a 100-m buffer of NHD streams. Original NLCD 2006 water cells adjacent to NHD stream lines used to expand NHD stream lines to full water area | L11: Square Kilometers | M11: NHDPlusV2 | N11: Tables with Rp100 metrics
A12: n | B12: Base | C12: Base | D12: Area | E12: catpctfull[AOI] | F12: catpctfull | H12: Cat, CatRp100 | J12: Percent Full | K12: Percent of the AOI that is covered by the landscape layer. | L12: Percent | M12: NHDPlusV2 | N12: All
A13: y | B13: Anthropogenic | C13: Nutrients | D13: Agriculture | E13: cbnf[AOI] | F13: cbnf | H13: Cat, Ws | J13: Cultivated Biological Nitrogen Fixation Mean Rate | K13: Mean rate of biological nitrogen fixation from the cultivation of crops in kg N/ha/yr, within AOI | L13: Kilogram/Hectar/Year | M13: EnviroAtlas | N13: Agricultural Nitrogen
... A25: y | B25: Anthropogenic | C25: Anthropogenic | D25: IWI | E25: habt[AOI] | F25: habt | H25: Cat, Ws | J25: HABT | K25: Habitat provision component score calculated using AOI metrics | L25: Unitless | M25: Johnson et al. 2019 | N25: Index of Watershed Integrity
A26: y | B26: Anthropogenic | C26: Anthropogenic | D26: Urban | E26: huden[Year][AOI] | F26: huden2010 | H26: Cat, Ws, CatRp100, WsRp100 | I26: 2010 | J26: Mean Housing Density | K26: Mean housing unit density (housing units/square km) within AOI. | L26: Count/Square Kilometer | M26: US Census | N26: Census
A27: y | B27: Anthropogenic | C27: Anthropogenic | D27: IWI | E27: hyd[AOI] | F27: hyd | H27: Cat, Ws | J27: nan | K27: Hydrologic regulation component score calculated using AOI metrics | L27: Unitless | M27: Johson et al. 2019 | N27: Index of Watershed Integrity
A28: y | B28: Natural | C28: Natural | D28: Lithology | E28: hydrlcond[AOI] | F28: hydrlcond | H28: Cat, Ws | J28: Mean Hydraulic Conductivity | K28: Mean lithological hydraulic conductivity (micrometers per second) content in surface or near surface geology within AOI | L28: Percent | M28: USGS Sciencebase | N28: USGS Geochemistry
A29: y | B29: Anthropogenic | C29: Anthropogenic | D29: Other | E29: ici[AOI] | F29: ici | H29: Other | J29: ICI | K29: Revised Index of catchment integrity (version 2.1) based on Johnson et al. 2018 STOTEN | L29: Unitless | M29: Johnson et al. 2019 | N29: Index of Watershed Integrity
A30: y | B30: Natural | C30: Deposition | D30: Climate | E30: inorgnwetdep[Year][AOI] | F30: inorgnwetdep2008 | H30: Cat, Ws | I30: 2008 | J30: Mean Annual Precipitation-Weighted Nitrogen | K30: Annual gradient map of precipitation-weighted mean deposition for inorganic nitrogen wet deposition from nitrate and ammonium for 2008 in kg of N/ha/yr, within AOI | L30: Kilogram/Hectare/Year | M30: NADP | N30: NADP
A31: n | B31: Base | C31: Base | D31: Area | E31: instream | F31: instream | H31: Cat | K31: 1 = on-network lake and data were taken from StreamCat; 0 = off-network lake and custom AOIs was needed to generate LakeCat data | L31: Binary | N31: All
A32: y | B32: Anthropogenic | C32: Anthropogenic | D32: Other | E32: iwi[AOI] | F32: iwi | H32: Other | J32: IWI | K32: Revised Index of catchment integrity (version 2.1) based on Johnson et al. 2018 STOTEN | L32: Unitless | M32: Johnson et al. 2019 | N32: Index of Watershed Integrity
A33: y | B33: Natural | C33: Natural | D33: Lithology | E33: k2o[AOI] | F33: k2o | H33: Cat, Ws | J33: InorgNWetDep | K33: Mean % of lithological potassium oxide (K2O) content in surface or near surface geology within AOI | L33: Percent | M33: USGS Sciencebase | N33: USGS Geochemistry
A34: y | B34: Natural | C34: Soils | D34: Lithology | E34: kffact[AOI] | F34: kffact | H34: Cat, Ws | J34: Mean Soil Erodibility KF Factor | K34: Mean of STATSGO Kffactor raster within AOI. The Universal Soil Loss Equation (USLE) and represents a relative index of susceptibility of bare, cultivated soil to particle detachment and transport by rainfall | L34: Unitless | M34: Penn State Soil Info | N34: STATSGO Soils
A35: y | B35: Anthropogenic | C35: Nutrients | D35: Agriculture | E35: manure[AOI] | F35: manure | H35: Cat, Ws | J35: Mean Manure Application Rate | K35: Mean rate of manure application to agricultural land from confined animal feeding operations in kg N/ha/yr, within AOI | L35: Kilogram/Hectare/Year | M35: EnviroAtlas | N35: Agricultural Nitrogen
A36: y | B36: Natural | C36: Natural | D36: Other | E36: mast[Year] | F36: mast2008 | H36: Other | I36: 2008, 2009, 2013, 2014 | J36: Mean Annual Stream Temp | K36: Predicted mean annual stream temperature (Jan-Dec) for year 2008, 2009, 2013, 2014 | L36: Celsius | M36: Hill et al. 2013 | N36: Predicted Reference Stream Temperature
A37: y | B37: Natural | C37: Natural | D37: Lithology | E37: mgo[AOI] | F37: mgo | H37: Cat, Ws | J37: Mean Lithological Magnesium Oxide | K37: Mean % of lithological magnesium oxide (MgO) content in surface or near surface geology within AOI | L37: Percent | M37: USGS Sciencebase | N37: USGS Geochemistry
A38: y | B38: Anthropogenic | C38: Anthropogenic | D38: Mining_Toxics | E38: minedens[AOI] | F38: minedens | H38: Cat, Ws, CatRp100, WsRp100 | J38: Mine Density | K38: Density of mines sites within AOI (mines/square km) | L38: Count/Square Kilometer | M38: USGS | N38: Mines
A39: y | B39: Natural | C39: Natural | D39: Other | E39: msst[Year] | F39: msst2008 | H39: Other | I39: 2008, 2009, 2013, 2014 | J39: Mean Summer Stream Temp | K39: Predicted mean summer stream temperature (July-Aug) for years 2008, 2009, 2013, 2014 | L39: Celsius | M39: Hill et al. 2013 | N39: Predicted Reference Stream Temperature
A40: y | B40: Natural | C40: Natural | D40: Other | E40: mwst[Year] | F40: mwst2008 | H40: Other | I40: 2008, 2009, 2013, 2014 | J40: Mean Winter Stream Temp | K40: Predicted mean winter stream temperature (Jan-Feb) for year 2008, 2009, 2013, 2014 | L40: Percent | M40: Hill et al. 2013 | N40: Predicted Reference Stream Temperature
A41: y | B41: Natural | C41: Natural | D41: Lithology | E41: n[AOI] | F41: n | H41: Cat, Ws | J41: Mean Lithological Nitrogen | K41: Mean % of lithological nitrogen (N) content in surface or near surface geology within AOI | L41: Percent | M41: USGS Sciencebase | N41: USGS Geochemistry
A42: y | B42: Natural | C42: Natural | D42: Lithology | E42: na2o[AOI] | F42: na2o | H42: Cat, Ws | J42: Mean Lithological Sodium Oxide | K42: Mean % of lithological sodium oxide (Na2O) content in surface or near surface geology within AOI | L42: Percent | M42: USGS Sciencebase | N42: USGS Geochemistry
A43: y | B43: Anthropogenic | C43: Anthropogenic | D43: Dams | E43: NABD_Dens[AOI] | F43: NABD_Dens | H43: Cat, Ws | J43: NABD Dam Density | K43: Density of georeferenced dams within AOI (dams/ square km) | L43: Count/Square Kilometer | M43: USGS Sciencebase | N43: Dams
A44: y | B44: Anthropogenic | C44: Anthropogenic | D44: Dams | E44: NABD_NIDStor[AOI] | F44: NABD_NIDStor | H44: Cat, Ws | J44: NABD NID Reservoir Volume | K44: Volume all reservoirs (NID_STORA in NID) per unit area of AOI (cubic meters/square km) | L44: Cubic Meters/Square Kilometer | M44: USGS Sciencebase | N44: Dams
A45: y | B45: Anthropogenic | C45: Anthropogenic | D45: Dams | E45: NABD_NrmStor[AOI] | F45: NABD_NrmStor | H45: Cat, Ws | J45: NABD Normal Reservoir Volume | K45: Volume all reservoirs (NORM_STORA in NID) per unit area of AOI (cubic meters/square km) | L45: Cubic Meters/Square Kilometer | M45: USGS Sciencebase | N45: Dams
A46: y | B46: Anthropogenic | C46: Nutrients | D46: Agriculture | E46: nani[AOI] | F46: nani | H46: Cat, Ws | J46: Anthropogenic Nitrogen | K46: Net Anthropogenic Nitrogen within AOI: farm fertilizer + urban fertilizer + NOx deposition + CBNF + Human and Livestock food - crop N content - livestock N content | L46: Kilogram/Hectare/Year | M46: Pennino et al. 2020 | N46: NSURP NANI
A47: y | B47: Natural | C47: Deposition | D47: Climate | E47: nh4[Year][AOI] | F47: nh42008 | H47: Cat, Ws | I47: 2008 | J47: Mean annual Precipitation-Weighted NH4 Mean | K47: Annual gradient map of precipitation-weighted mean deposition for ammonium ion concentration wet deposition for 2008 in kg of NH4/ha/yr, within AOI | L47: Kilogram/Hectare/Year | M47: NADP | N47: NADP
A48: y | B48: Natural | C48: Deposition | D48: Climate | E48: no3[Year][AOI] | F48: no32008 | H48: Cat, Ws | I48: 2008 | J48: Mean Annual Precipitation-Weighted NO3 Mean | K48: Annual gradient map of precipitation-weighted mean deposition for nitrate ion concentration wet deposition for 2008 in kg of NO3/ha/yr, within AOI | L48: Kilogram/Hectare/Year | M48: NADP | N48: NADP
A49: y | B49: Anthropogenic | C49: Anthropogenic | D49: Urban | E49: npdesdens[AOI] | F49: npdesdens | H49: Cat, Ws, CatRp100, WsRp100 | J49: NPDES Site Density | K49: Density of permitted NPDES (National Pollutant Discharge Elimination System) sites within AOI (sites/square km) | L49: Count/Square Kilometer | M49: EPA FRS | N49: EPA FRS
A50: y | B50: Anthropogenic | C50: Nutrients | D50: Agriculture | E50: nsurp[AOI] | F50: nsurp | H50: Cat, Ws | J50: Nitrogen Surplus | K50: Nitrogen Surplus (kg N / yr) per AOI - excluding biological N Fixation | L50: Percent | M50: Pennino et al. 2020 | N50: NSURP NANI
A51: y | B51: Natural | C51: Soils | D51: Lithology | E51: om[AOI] | F51: om | H51: Cat, Ws | J51: Organic Matter Mean | K51: Mean organic matter content (% by weight) of soils (STATSGO) within AOI | L51: Percent | M51: Carlisle et al. 2009 | N51: STATSGO Soils
...
