Workbook

Sheet Spearmans2
A1: rowname | B1: rowname minus ws | C1: Name | D1: Category | E1: Subcategory | F1: Metric description | G1: Name | H1: Category | I1: Subcategory | J1: Metric description | K1: colname | M1: Name | N1: Category | O1: Description | P1: Name | Q1: Category | R1: Description | S1: cor
A2: AGKFFACTWS | B2: =IF(RIGHT(A2,2)="WS", LEFT(A2,LEN(A2)-2),A2) -> AGKFFACT | C2: =INDEX(Active!J:J, MATCH(Spearmans2!B2, Active!F:F,0),1) -> Ag Soil Erodibility Kf Factor | D2: =INDEX(Active!B:B, MATCH(Spearmans2!B2, Active!F:F,0),1) -> Anthropogenic | E2: =INDEX(Active!D:D, MATCH(Spearmans2!B2, Active!F:F,0),1) -> Agriculture | F2: =INDEX(Active!K:K, MATCH(Spearmans2!B2, Active!F:F,0),1) -> Mean of STATSGO Kffactor raster on agricultural land (NLCD 2006) within AOI. The Universal Soil Loss Equation (USLE) and represents a relative index of susceptibility of bare, cultivated soil to particle detachment and transport by rainfall | G2: Ag Soil Erodibility Kf Factor | H2: Anthropogenic | I2: Agriculture | J2: Mean of STATSGO Kffactor raster on agricultural land (NLCD 2006) within AOI. The Universal Soil Loss Equation (USLE) and represents a relative index of susceptibility of bare, cultivated soil to particle detachment and transport by rainfall | K2: MANUREWS | L2: =IF(RIGHT(K2,2)="WS", LEFT(K2,LEN(K2)-2),K2) -> MANURE | M2: =INDEX(Active!J:J, MATCH(Spearmans2!L2, Active!F:F,0),1) -> Mean Manure Application Rate | N2: =INDEX(Active!B:B, MATCH(Spearmans2!L2, Active!F:F,0),1) -> Anthropogenic | O2: =INDEX(Active!K:K, MATCH(Spearmans2!L2, Active!F:F,0),1) -> Mean rate of manure application to agricultural land from confined animal feeding operations in kg N/ha/yr, within AOI | P2: Mean Manure Application Rate | Q2: Anthropogenic | R2: Mean rate of manure application to agricultural land from confined animal feeding operations in kg N/ha/yr, within AOI | S2: 0.85980818
A3: AGKFFACTWS | B3: =IF(RIGHT(A3,2)="WS", LEFT(A3,LEN(A3)-2),A3) -> AGKFFACT | C3: =INDEX(Active!J:J, MATCH(Spearmans2!B3, Active!F:F,0),1) -> Ag Soil Erodibility Kf Factor | D3: =INDEX(Active!B:B, MATCH(Spearmans2!B3, Active!F:F,0),1) -> Anthropogenic | E3: =INDEX(Active!D:D, MATCH(Spearmans2!B3, Active!F:F,0),1) -> Agriculture | F3: =INDEX(Active!K:K, MATCH(Spearmans2!B3, Active!F:F,0),1) -> Mean of STATSGO Kffactor raster on agricultural land (NLCD 2006) within AOI. The Universal Soil Loss Equation (USLE) and represents a relative index of susceptibility of bare, cultivated soil to particle detachment and transport by rainfall | G3: Ag Soil Erodibility Kf Factor | H3: Anthropogenic | I3: Agriculture | J3: Mean of STATSGO Kffactor raster on agricultural land (NLCD 2006) within AOI. The Universal Soil Loss Equation (USLE) and represents a relative index of susceptibility of bare, cultivated soil to particle detachment and transport by rainfall | K3: WATERINPUTWS | L3: =IF(RIGHT(K3,2)="WS", LEFT(K3,LEN(K3)-2),K3) -> WATERINPUT | M3: =INDEX(Active!J:J, MATCH(Spearmans2!L3, Active!F:F,0),1) -> Water Input | N3: =INDEX(Active!B:B, MATCH(Spearmans2!L3, Active!F:F,0),1) -> Anthropogenic | O3: =INDEX(Active!K:K, MATCH(Spearmans2!L3, Active!F:F,0),1) -> Water Input (km2/cm): Ratio of the total area of irrigated land to precipitation within AOI | P3: Water Input | Q3: Anthropogenic | R3: Water Input (km2/cm): Ratio of the total area of irrigated land to precipitation within AOI | S3: 0.92901414
A4: AGKFFACTWS | B4: =IF(RIGHT(A4,2)="WS", LEFT(A4,LEN(A4)-2),A4) -> AGKFFACT | C4: =INDEX(Active!J:J, MATCH(Spearmans2!B4, Active!F:F,0),1) -> Ag Soil Erodibility Kf Factor | D4: =INDEX(Active!B:B, MATCH(Spearmans2!B4, Active!F:F,0),1) -> Anthropogenic | E4: =INDEX(Active!D:D, MATCH(Spearmans2!B4, Active!F:F,0),1) -> Agriculture | F4: =INDEX(Active!K:K, MATCH(Spearmans2!B4, Active!F:F,0),1) -> Mean of STATSGO Kffactor raster on agricultural land (NLCD 2006) within AOI. The Universal Soil Loss Equation (USLE) and represents a relative index of susceptibility of bare, cultivated soil to particle detachment and transport by rainfall | G4: Ag Soil Erodibility Kf Factor | H4: Anthropogenic | I4: Agriculture | J4: Mean of STATSGO Kffactor raster on agricultural land (NLCD 2006) within AOI. The Universal Soil Loss Equation (USLE) and represents a relative index of susceptibility of bare, cultivated soil to particle detachment and transport by rainfall | K4: WDRW_LDWS | L4: =IF(RIGHT(K4,2)="WS", LEFT(K4,LEN(K4)-2),K4) -> WDRW_LD | M4: =INDEX(Active!J:J, MATCH(Spearmans2!L4, Active!F:F,0),1) -> Agricultural Fresh Surface-Water Withdraw | N4: =INDEX(Active!B:B, MATCH(Spearmans2!L4, Active!F:F,0),1) -> Anthropogenic | O4: =INDEX(Active!K:K, MATCH(Spearmans2!L4, Active!F:F,0),1) -> Total fresh surface-water withdrawals in agricultural land per AOI area (L/day) | P4: Agricultural Fresh Surface-Water Withdraw | Q4: Anthropogenic | R4: Total fresh surface-water withdrawals in agricultural land per AOI area (L/day) | S4: 0.95018592
A5: AGKFFACTWS | B5: =IF(RIGHT(A5,2)="WS", LEFT(A5,LEN(A5)-2),A5) -> AGKFFACT | C5: =INDEX(Active!J:J, MATCH(Spearmans2!B5, Active!F:F,0),1) -> Ag Soil Erodibility Kf Factor | D5: =INDEX(Active!B:B, MATCH(Spearmans2!B5, Active!F:F,0),1) -> Anthropogenic | E5: =INDEX(Active!D:D, MATCH(Spearmans2!B5, Active!F:F,0),1) -> Agriculture | F5: =INDEX(Active!K:K, MATCH(Spearmans2!B5, Active!F:F,0),1) -> Mean of STATSGO Kffactor raster on agricultural land (NLCD 2006) within AOI. The Universal Soil Loss Equation (USLE) and represents a relative index of susceptibility of bare, cultivated soil to particle detachment and transport by rainfall | G5: Ag Soil Erodibility Kf Factor | H5: Anthropogenic | I5: Agriculture | J5: Mean of STATSGO Kffactor raster on agricultural land (NLCD 2006) within AOI. The Universal Soil Loss Equation (USLE) and represents a relative index of susceptibility of bare, cultivated soil to particle detachment and transport by rainfall | K5: CBNFWS | L5: =IF(RIGHT(K5,2)="WS", LEFT(K5,LEN(K5)-2),K5) -> CBNF | M5: =INDEX(Active!J:J, MATCH(Spearmans2!L5, Active!F:F,0),1) -> Cultivated Biological Nitrogen Fixation Mean Rate | N5: =INDEX(Active!B:B, MATCH(Spearmans2!L5, Active!F:F,0),1) -> Anthropogenic | O5: =INDEX(Active!K:K, MATCH(Spearmans2!L5, Active!F:F,0),1) -> Mean rate of biological nitrogen fixation from the cultivation of crops in kg N/ha/yr, within AOI | P5: Cultivated Biological Nitrogen Fixation Mean Rate | Q5: Anthropogenic | R5: Mean rate of biological nitrogen fixation from the cultivation of crops in kg N/ha/yr, within AOI | S5: 0.98132303
A6: AGKFFACTWS | B6: =IF(RIGHT(A6,2)="WS", LEFT(A6,LEN(A6)-2),A6) -> AGKFFACT | C6: =INDEX(Active!J:J, MATCH(Spearmans2!B6, Active!F:F,0),1) -> Ag Soil Erodibility Kf Factor | D6: =INDEX(Active!B:B, MATCH(Spearmans2!B6, Active!F:F,0),1) -> Anthropogenic | E6: =INDEX(Active!D:D, MATCH(Spearmans2!B6, Active!F:F,0),1) -> Agriculture | F6: =INDEX(Active!K:K, MATCH(Spearmans2!B6, Active!F:F,0),1) -> Mean of STATSGO Kffactor raster on agricultural land (NLCD 2006) within AOI. The Universal Soil Loss Equation (USLE) and represents a relative index of susceptibility of bare, cultivated soil to particle detachment and transport by rainfall | G6: Ag Soil Erodibility Kf Factor | H6: Anthropogenic | I6: Agriculture | J6: Mean of STATSGO Kffactor raster on agricultural land (NLCD 2006) within AOI. The Universal Soil Loss Equation (USLE) and represents a relative index of susceptibility of bare, cultivated soil to particle detachment and transport by rainfall | K6: FERTWS | L6: =IF(RIGHT(K6,2)="WS", LEFT(K6,LEN(K6)-2),K6) -> FERT | M6: =INDEX(Active!J:J, MATCH(Spearmans2!L6, Active!F:F,0),1) -> Synthetic Nitrogen Fertilizer Application Mean Rate | N6: =INDEX(Active!B:B, MATCH(Spearmans2!L6, Active!F:F,0),1) -> Anthropogenic | O6: =INDEX(Active!K:K, MATCH(Spearmans2!L6, Active!F:F,0),1) -> Mean rate of synthetic nitrogen fertilizer application to agricultural land in kg N/ha/yr, within the AOI | P6: Synthetic Nitrogen Fertilizer Application Mean Rate | Q6: Anthropogenic | R6: Mean rate of synthetic nitrogen fertilizer application to agricultural land in kg N/ha/yr, within the AOI | S6: 0.98849025
A7: AL2O3WS | B7: =IF(RIGHT(A7,2)="WS", LEFT(A7,LEN(A7)-2),A7) -> AL2O3 | C7: =INDEX(Active!J:J, MATCH(Spearmans2!B7, Active!F:F,0),1) -> Mean Lithological Aluminum Oxide | D7: =INDEX(Active!B:B, MATCH(Spearmans2!B7, Active!F:F,0),1) -> Natural | E7: =INDEX(Active!D:D, MATCH(Spearmans2!B7, Active!F:F,0),1) -> Lithology | F7: =INDEX(Active!K:K, MATCH(Spearmans2!B7, Active!F:F,0),1) -> Mean % of lithological aluminum oxide (Al2O3) content in surface or near surface geology within AOI | G7: Mean Lithological Aluminum Oxide | H7: Natural | I7: Lithology | J7: Mean % of lithological aluminum oxide (Al2O3) content in surface or near surface geology within AOI | K7: CAOWS | L7: =IF(RIGHT(K7,2)="WS", LEFT(K7,LEN(K7)-2),K7) -> CAO | M7: =INDEX(Active!J:J, MATCH(Spearmans2!L7, Active!F:F,0),1) -> Mean Lithological Calcium Oxide | N7: =INDEX(Active!B:B, MATCH(Spearmans2!L7, Active!F:F,0),1) -> Natural | O7: =INDEX(Active!K:K, MATCH(Spearmans2!L7, Active!F:F,0),1) -> Mean % of lithological calcium oxide (CaO) content in surface or near surface geology within AOI | P7: Mean Lithological Calcium Oxide | Q7: Natural | R7: Mean % of lithological calcium oxide (CaO) content in surface or near surface geology within AOI | S7: 0.82627092
A8: AL2O3WS | B8: =IF(RIGHT(A8,2)="WS", LEFT(A8,LEN(A8)-2),A8) -> AL2O3 | C8: =INDEX(Active!J:J, MATCH(Spearmans2!B8, Active!F:F,0),1) -> Mean Lithological Aluminum Oxide | D8: =INDEX(Active!B:B, MATCH(Spearmans2!B8, Active!F:F,0),1) -> Natural | E8: =INDEX(Active!D:D, MATCH(Spearmans2!B8, Active!F:F,0),1) -> Lithology | F8: =INDEX(Active!K:K, MATCH(Spearmans2!B8, Active!F:F,0),1) -> Mean % of lithological aluminum oxide (Al2O3) content in surface or near surface geology within AOI | G8: Mean Lithological Aluminum Oxide | H8: Natural | I8: Lithology | J8: Mean % of lithological aluminum oxide (Al2O3) content in surface or near surface geology within AOI | K8: P2O5WS | L8: =IF(RIGHT(K8,2)="WS", LEFT(K8,LEN(K8)-2),K8) -> P2O5 | M8: =INDEX(Active!J:J, MATCH(Spearmans2!L8, Active!F:F,0),1) -> Mean Lithological Phosphorous Oxide | N8: =INDEX(Active!B:B, MATCH(Spearmans2!L8, Active!F:F,0),1) -> Natural | O8: =INDEX(Active!K:K, MATCH(Spearmans2!L8, Active!F:F,0),1) -> Mean % of lithological phosphorous oxide (P2O5) content in surface or near surface geology within AOI | P8: Mean Lithological Phosphorous Oxide | Q8: Natural | R8: Mean % of lithological phosphorous oxide (P2O5) content in surface or near surface geology within AOI | S8: 0.87560554
A9: AL2O3WS | B9: =IF(RIGHT(A9,2)="WS", LEFT(A9,LEN(A9)-2),A9) -> AL2O3 | C9: =INDEX(Active!J:J, MATCH(Spearmans2!B9, Active!F:F,0),1) -> Mean Lithological Aluminum Oxide | D9: =INDEX(Active!B:B, MATCH(Spearmans2!B9, Active!F:F,0),1) -> Natural | E9: =INDEX(Active!D:D, MATCH(Spearmans2!B9, Active!F:F,0),1) -> Lithology | F9: =INDEX(Active!K:K, MATCH(Spearmans2!B9, Active!F:F,0),1) -> Mean % of lithological aluminum oxide (Al2O3) content in surface or near surface geology within AOI | G9: Mean Lithological Aluminum Oxide | H9: Natural | I9: Lithology | J9: Mean % of lithological aluminum oxide (Al2O3) content in surface or near surface geology within AOI | K9: NA2OWS | L9: =IF(RIGHT(K9,2)="WS", LEFT(K9,LEN(K9)-2),K9) -> NA2O | M9: =INDEX(Active!J:J, MATCH(Spearmans2!L9, Active!F:F,0),1) -> Mean Lithological Sodium Oxide | N9: =INDEX(Active!B:B, MATCH(Spearmans2!L9, Active!F:F,0),1) -> Natural | O9: =INDEX(Active!K:K, MATCH(Spearmans2!L9, Active!F:F,0),1) -> Mean % of lithological sodium oxide (Na2O) content in surface or near surface geology within AOI | P9: Mean Lithological Sodium Oxide | Q9: Natural | R9: Mean % of lithological sodium oxide (Na2O) content in surface or near surface geology within AOI | S9: 0.93978313
A10: BANKFULLDEPTH | B10: =IF(RIGHT(A10,2)="WS", LEFT(A10,LEN(A10)-2),A10) -> BANKFULLDEPTH | C10: =INDEX(Active!J:J, MATCH(Spearmans2!B10, Active!F:F,0),1) -> Predicted Bankfull Depth | D10: =INDEX(Active!B:B, MATCH(Spearmans2!B10, Active!F:F,0),1) -> Natural | E10: =INDEX(Active!D:D, MATCH(Spearmans2!B10, Active!F:F,0),1) -> Other | F10: =INDEX(Active!K:K, MATCH(Spearmans2!B10, Active!F:F,0),1) -> Predicted bankfull depth: thalweg depth plus bankfull height, which is the height from the water surface to the bankfull stage | G10: Predicted Bankfull Depth | H10: Natural | I10: Other | J10: Predicted bankfull depth: thalweg depth plus bankfull height, which is the height from the water surface to the bankfull stage | K10: NANIWS | L10: =IF(RIGHT(K10,2)="WS", LEFT(K10,LEN(K10)-2),K10) -> NANI | M10: =INDEX(Active!J:J, MATCH(Spearmans2!L10, Active!F:F,0),1) -> Anthropogenic Nitrogen | N10: =INDEX(Active!B:B, MATCH(Spearmans2!L10, Active!F:F,0),1) -> Anthropogenic | O10: =INDEX(Active!K:K, MATCH(Spearmans2!L10, Active!F:F,0),1) -> Net Anthropogenic Nitrogen within AOI: farm fertilizer + urban fertilizer + NOx deposition + CBNF + Human and Livestock food - crop N content - livestock N content | P10: Anthropogenic Nitrogen | Q10: Anthropogenic | R10: Net Anthropogenic Nitrogen within AOI: farm fertilizer + urban fertilizer + NOx deposition + CBNF + Human and Livestock food - crop N content - livestock N content | S10: 0.81113226
A11: BANKFULLDEPTH | B11: =IF(RIGHT(A11,2)="WS", LEFT(A11,LEN(A11)-2),A11) -> BANKFULLDEPTH | C11: =INDEX(Active!J:J, MATCH(Spearmans2!B11, Active!F:F,0),1) -> Predicted Bankfull Depth | D11: =INDEX(Active!B:B, MATCH(Spearmans2!B11, Active!F:F,0),1) -> Natural | E11: =INDEX(Active!D:D, MATCH(Spearmans2!B11, Active!F:F,0),1) -> Other | F11: =INDEX(Active!K:K, MATCH(Spearmans2!B11, Active!F:F,0),1) -> Predicted bankfull depth: thalweg depth plus bankfull height, which is the height from the water surface to the bankfull stage | G11: Predicted Bankfull Depth | H11: Natural | I11: Other | J11: Predicted bankfull depth: thalweg depth plus bankfull height, which is the height from the water surface to the bankfull stage | K11: NSURPWS | L11: =IF(RIGHT(K11,2)="WS", LEFT(K11,LEN(K11)-2),K11) -> NSURP | M11: =INDEX(Active!J:J, MATCH(Spearmans2!L11, Active!F:F,0),1) -> Nitrogen Surplus | N11: =INDEX(Active!B:B, MATCH(Spearmans2!L11, Active!F:F,0),1) -> Anthropogenic | O11: =INDEX(Active!K:K, MATCH(Spearmans2!L11, Active!F:F,0),1) -> Nitrogen Surplus (kg N / yr) per AOI - excluding biological N Fixation | P11: Nitrogen Surplus | Q11: Anthropogenic | R11: Nitrogen Surplus (kg N / yr) per AOI - excluding biological N Fixation | S11: 0.82065462
A12: BANKFULLDEPTH | B12: =IF(RIGHT(A12,2)="WS", LEFT(A12,LEN(A12)-2),A12) -> BANKFULLDEPTH | C12: =INDEX(Active!J:J, MATCH(Spearmans2!B12, Active!F:F,0),1) -> Predicted Bankfull Depth | D12: =INDEX(Active!B:B, MATCH(Spearmans2!B12, Active!F:F,0),1) -> Natural | E12: =INDEX(Active!D:D, MATCH(Spearmans2!B12, Active!F:F,0),1) -> Other | F12: =INDEX(Active!K:K, MATCH(Spearmans2!B12, Active!F:F,0),1) -> Predicted bankfull depth: thalweg depth plus bankfull height, which is the height from the water surface to the bankfull stage | G12: Predicted Bankfull Depth | H12: Natural | I12: Other | J12: Predicted bankfull depth: thalweg depth plus bankfull height, which is the height from the water surface to the bankfull stage | K12: THALWEGDEPTH | L12: =IF(RIGHT(K12,2)="WS", LEFT(K12,LEN(K12)-2),K12) -> THALWEGDEPTH | M12: =INDEX(Active!J:J, MATCH(Spearmans2!L12, Active!F:F,0),1) -> #N/A | N12: =INDEX(Active!B:B, MATCH(Spearmans2!L12, Active!F:F,0),1) -> #N/A | O12: =INDEX(Active!K:K, MATCH(Spearmans2!L12, Active!F:F,0),1) -> #N/A | P12: #N/A | Q12: #N/A | R12: #N/A | S12: 0.92610251
A13: BANKFULLDEPTH | B13: =IF(RIGHT(A13,2)="WS", LEFT(A13,LEN(A13)-2),A13) -> BANKFULLDEPTH | C13: =INDEX(Active!J:J, MATCH(Spearmans2!B13, Active!F:F,0),1) -> Predicted Bankfull Depth | D13: =INDEX(Active!B:B, MATCH(Spearmans2!B13, Active!F:F,0),1) -> Natural | E13: =INDEX(Active!D:D, MATCH(Spearmans2!B13, Active!F:F,0),1) -> Other | F13: =INDEX(Active!K:K, MATCH(Spearmans2!B13, Active!F:F,0),1) -> Predicted bankfull depth: thalweg depth plus bankfull height, which is the height from the water surface to the bankfull stage | G13: Predicted Bankfull Depth | H13: Natural | I13: Other | J13: Predicted bankfull depth: thalweg depth plus bankfull height, which is the height from the water surface to the bankfull stage | K13: WETTEDWIDTH | L13: =IF(RIGHT(K13,2)="WS", LEFT(K13,LEN(K13)-2),K13) -> WETTEDWIDTH | M13: =INDEX(Active!J:J, MATCH(Spearmans2!L13, Active!F:F,0),1) -> Predicted Wetted Width | N13: =INDEX(Active!B:B, MATCH(Spearmans2!L13, Active!F:F,0),1) -> Natural | O13: =INDEX(Active!K:K, MATCH(Spearmans2!L13, Active!F:F,0),1) -> Predicted wetted width: distance of the waters edge from left to right bank | P13: Predicted Wetted Width | Q13: Natural | R13: Predicted wetted width: distance of the waters edge from left to right bank | S13: 0.94009985
A14: BANKFULLDEPTH | B14: =IF(RIGHT(A14,2)="WS", LEFT(A14,LEN(A14)-2),A14) -> BANKFULLDEPTH | C14: =INDEX(Active!J:J, MATCH(Spearmans2!B14, Active!F:F,0),1) -> Predicted Bankfull Depth | D14: =INDEX(Active!B:B, MATCH(Spearmans2!B14, Active!F:F,0),1) -> Natural | E14: =INDEX(Active!D:D, MATCH(Spearmans2!B14, Active!F:F,0),1) -> Other | F14: =INDEX(Active!K:K, MATCH(Spearmans2!B14, Active!F:F,0),1) -> Predicted bankfull depth: thalweg depth plus bankfull height, which is the height from the water surface to the bankfull stage | G14: Predicted Bankfull Depth | H14: Natural | I14: Other | J14: Predicted bankfull depth: thalweg depth plus bankfull height, which is the height from the water surface to the bankfull stage | K14: BANKFULLWIDTH | L14: =IF(RIGHT(K14,2)="WS", LEFT(K14,LEN(K14)-2),K14) -> BANKFULLWIDTH | M14: =INDEX(Active!J:J, MATCH(Spearmans2!L14, Active!F:F,0),1) -> Predicted Bankfull Width | N14: =INDEX(Active!B:B, MATCH(Spearmans2!L14, Active!F:F,0),1) -> Natural | O14: =INDEX(Active!K:K, MATCH(Spearmans2!L14, Active!F:F,0),1) -> Predicted bankfull width: distance from left to right bank at bankfull stage where the potential water height would spill outside of the channel and into the floodplain | P14: Predicted Bankfull Width | Q14: Natural | R14: Predicted bankfull width: distance from left to right bank at bankfull stage where the potential water height would spill outside of the channel and into the floodplain | S14: 0.94204504
A15: BANKFULLWIDTH | B15: =IF(RIGHT(A15,2)="WS", LEFT(A15,LEN(A15)-2),A15) -> BANKFULLWIDTH | C15: =INDEX(Active!J:J, MATCH(Spearmans2!B15, Active!F:F,0),1) -> Predicted Bankfull Width | D15: =INDEX(Active!B:B, MATCH(Spearmans2!B15, Active!F:F,0),1) -> Natural | E15: =INDEX(Active!D:D, MATCH(Spearmans2!B15, Active!F:F,0),1) -> Other | F15: =INDEX(Active!K:K, MATCH(Spearmans2!B15, Active!F:F,0),1) -> Predicted bankfull width: distance from left to right bank at bankfull stage where the potential water height would spill outside of the channel and into the floodplain | G15: Predicted Bankfull Width | H15: Natural | I15: Other | J15: Predicted bankfull width: distance from left to right bank at bankfull stage where the potential water height would spill outside of the channel and into the floodplain | K15: NANIWS | L15: =IF(RIGHT(K15,2)="WS", LEFT(K15,LEN(K15)-2),K15) -> NANI | M15: =INDEX(Active!J:J, MATCH(Spearmans2!L15, Active!F:F,0),1) -> Anthropogenic Nitrogen | N15: =INDEX(Active!B:B, MATCH(Spearmans2!L15, Active!F:F,0),1) -> Anthropogenic | O15: =INDEX(Active!K:K, MATCH(Spearmans2!L15, Active!F:F,0),1) -> Net Anthropogenic Nitrogen within AOI: farm fertilizer + urban fertilizer + NOx deposition + CBNF + Human and Livestock food - crop N content - livestock N content | P15: Anthropogenic Nitrogen | Q15: Anthropogenic | R15: Net Anthropogenic Nitrogen within AOI: farm fertilizer + urban fertilizer + NOx deposition + CBNF + Human and Livestock food - crop N content - livestock N content | S15: 0.83988426
A16: BANKFULLWIDTH | B16: =IF(RIGHT(A16,2)="WS", LEFT(A16,LEN(A16)-2),A16) -> BANKFULLWIDTH | C16: =INDEX(Active!J:J, MATCH(Spearmans2!B16, Active!F:F,0),1) -> Predicted Bankfull Width | D16: =INDEX(Active!B:B, MATCH(Spearmans2!B16, Active!F:F,0),1) -> Natural | E16: =INDEX(Active!D:D, MATCH(Spearmans2!B16, Active!F:F,0),1) -> Other | F16: =INDEX(Active!K:K, MATCH(Spearmans2!B16, Active!F:F,0),1) -> Predicted bankfull width: distance from left to right bank at bankfull stage where the potential water height would spill outside of the channel and into the floodplain | G16: Predicted Bankfull Width | H16: Natural | I16: Other | J16: Predicted bankfull width: distance from left to right bank at bankfull stage where the potential water height would spill outside of the channel and into the floodplain | K16: NSURPWS | L16: =IF(RIGHT(K16,2)="WS", LEFT(K16,LEN(K16)-2),K16) -> NSURP | M16: =INDEX(Active!J:J, MATCH(Spearmans2!L16, Active!F:F,0),1) -> Nitrogen Surplus | N16: =INDEX(Active!B:B, MATCH(Spearmans2!L16, Active!F:F,0),1) -> Anthropogenic | O16: =INDEX(Active!K:K, MATCH(Spearmans2!L16, Active!F:F,0),1) -> Nitrogen Surplus (kg N / yr) per AOI - excluding biological N Fixation | P16: Nitrogen Surplus | Q16: Anthropogenic | R16: Nitrogen Surplus (kg N / yr) per AOI - excluding biological N Fixation | S16: 0.84577613
A17: BANKFULLWIDTH | B17: =IF(RIGHT(A17,2)="WS", LEFT(A17,LEN(A17)-2),A17) -> BANKFULLWIDTH | C17: =INDEX(Active!J:J, MATCH(Spearmans2!B17, Active!F:F,0),1) -> Predicted Bankfull Width | D17: =INDEX(Active!B:B, MATCH(Spearmans2!B17, Active!F:F,0),1) -> Natural | E17: =INDEX(Active!D:D, MATCH(Spearmans2!B17, Active!F:F,0),1) -> Other | F17: =INDEX(Active!K:K, MATCH(Spearmans2!B17, Active!F:F,0),1) -> Predicted bankfull width: distance from left to right bank at bankfull stage where the potential water height would spill outside of the channel and into the floodplain | G17: Predicted Bankfull Width | H17: Natural | I17: Other | J17: Predicted bankfull width: distance from left to right bank at bankfull stage where the potential water height would spill outside of the channel and into the floodplain | K17: BANKFULLDEPTH | L17: =IF(RIGHT(K17,2)="WS", LEFT(K17,LEN(K17)-2),K17) -> BANKFULLDEPTH | M17: =INDEX(Active!J:J, MATCH(Spearmans2!L17, Active!F:F,0),1) -> Predicted Bankfull Depth | N17: =INDEX(Active!B:B, MATCH(Spearmans2!L17, Active!F:F,0),1) -> Natural | O17: =INDEX(Active!K:K, MATCH(Spearmans2!L17, Active!F:F,0),1) -> Predicted bankfull depth: thalweg depth plus bankfull height, which is the height from the water surface to the bankfull stage | P17: Predicted Bankfull Depth | Q17: Natural | R17: Predicted bankfull depth: thalweg depth plus bankfull height, which is the height from the water surface to the bankfull stage | S17: 0.94204504
A18: BANKFULLWIDTH | B18: =IF(RIGHT(A18,2)="WS", LEFT(A18,LEN(A18)-2),A18) -> BANKFULLWIDTH | C18: =INDEX(Active!J:J, MATCH(Spearmans2!B18, Active!F:F,0),1) -> Predicted Bankfull Width | D18: =INDEX(Active!B:B, MATCH(Spearmans2!B18, Active!F:F,0),1) -> Natural | E18: =INDEX(Active!D:D, MATCH(Spearmans2!B18, Active!F:F,0),1) -> Other | F18: =INDEX(Active!K:K, MATCH(Spearmans2!B18, Active!F:F,0),1) -> Predicted bankfull width: distance from left to right bank at bankfull stage where the potential water height would spill outside of the channel and into the floodplain | G18: Predicted Bankfull Width | H18: Natural | I18: Other | J18: Predicted bankfull width: distance from left to right bank at bankfull stage where the potential water height would spill outside of the channel and into the floodplain | K18: THALWEGDEPTH | L18: =IF(RIGHT(K18,2)="WS", LEFT(K18,LEN(K18)-2),K18) -> THALWEGDEPTH | M18: =INDEX(Active!J:J, MATCH(Spearmans2!L18, Active!F:F,0),1) -> #N/A | N18: =INDEX(Active!B:B, MATCH(Spearmans2!L18, Active!F:F,0),1) -> #N/A | O18: =INDEX(Active!K:K, MATCH(Spearmans2!L18, Active!F:F,0),1) -> #N/A | P18: #N/A | Q18: #N/A | R18: #N/A | S18: 0.95847251
A19: BANKFULLWIDTH | B19: =IF(RIGHT(A19,2)="WS", LEFT(A19,LEN(A19)-2),A19) -> BANKFULLWIDTH | C19: =INDEX(Active!J:J, MATCH(Spearmans2!B19, Active!F:F,0),1) -> Predicted Bankfull Width | D19: =INDEX(Active!B:B, MATCH(Spearmans2!B19, Active!F:F,0),1) -> Natural | E19: =INDEX(Active!D:D, MATCH(Spearmans2!B19, Active!F:F,0),1) -> Other | F19: =INDEX(Active!K:K, MATCH(Spearmans2!B19, Active!F:F,0),1) -> Predicted bankfull width: distance from left to right bank at bankfull stage where the potential water height would spill outside of the channel and into the floodplain | G19: Predicted Bankfull Width | H19: Natural | I19: Other | J19: Predicted bankfull width: distance from left to right bank at bankfull stage where the potential water height would spill outside of the channel and into the floodplain | K19: WETTEDWIDTH | L19: =IF(RIGHT(K19,2)="WS", LEFT(K19,LEN(K19)-2),K19) -> WETTEDWIDTH | M19: =INDEX(Active!J:J, MATCH(Spearmans2!L19, Active!F:F,0),1) -> Predicted Wetted Width | N19: =INDEX(Active!B:B, MATCH(Spearmans2!L19, Active!F:F,0),1) -> Natural | O19: =INDEX(Active!K:K, MATCH(Spearmans2!L19, Active!F:F,0),1) -> Predicted wetted width: distance of the waters edge from left to right bank | P19: Predicted Wetted Width | Q19: Natural | R19: Predicted wetted width: distance of the waters edge from left to right bank | S19: 0.99082893
A20: BFIWS | B20: =IF(RIGHT(A20,2)="WS", LEFT(A20,LEN(A20)-2),A20) -> BFI | C20: =INDEX(Active!J:J, MATCH(Spearmans2!B20, Active!F:F,0),1) -> Base Flow Index | D20: =INDEX(Active!B:B, MATCH(Spearmans2!B20, Active!F:F,0),1) -> Natural | E20: =INDEX(Active!D:D, MATCH(Spearmans2!B20, Active!F:F,0),1) -> Flow | F20: =INDEX(Active!K:K, MATCH(Spearmans2!B20, Active!F:F,0),1) -> Base flow is the component of streamflow that can be attributed to ground-water discharge into streams. The BFI is the ratio of base flow to total flow, expressed as a percentage, within AOI | G20: Base Flow Index | H20: Natural | I20: Flow | J20: Base flow is the component of streamflow that can be attributed to ground-water discharge into streams. The BFI is the ratio of base flow to total flow, expressed as a percentage, within AOI | K20: MAST2008 | L20: =IF(RIGHT(K20,2)="WS", LEFT(K20,LEN(K20)-2),K20) -> MAST2008 | M20: =INDEX(Active!J:J, MATCH(Spearmans2!L20, Active!F:F,0),1) -> Mean Annual Stream Temp | N20: =INDEX(Active!B:B, MATCH(Spearmans2!L20, Active!F:F,0),1) -> Natural | O20: =INDEX(Active!K:K, MATCH(Spearmans2!L20, Active!F:F,0),1) -> Predicted mean annual stream temperature (Jan-Dec) for year 2008, 2009, 2013, 2014 | P20: Mean Annual Stream Temp | Q20: Natural | R20: Predicted mean annual stream temperature (Jan-Dec) for year 2008, 2009, 2013, 2014 | S20: -0.85416733
A21: BFIWS | B21: =IF(RIGHT(A21,2)="WS", LEFT(A21,LEN(A21)-2),A21) -> BFI | C21: =INDEX(Active!J:J, MATCH(Spearmans2!B21, Active!F:F,0),1) -> Base Flow Index | D21: =INDEX(Active!B:B, MATCH(Spearmans2!B21, Active!F:F,0),1) -> Natural | E21: =INDEX(Active!D:D, MATCH(Spearmans2!B21, Active!F:F,0),1) -> Flow | F21: =INDEX(Active!K:K, MATCH(Spearmans2!B21, Active!F:F,0),1) -> Base flow is the component of streamflow that can be attributed to ground-water discharge into streams. The BFI is the ratio of base flow to total flow, expressed as a percentage, within AOI | G21: Base Flow Index | H21: Natural | I21: Flow | J21: Base flow is the component of streamflow that can be attributed to ground-water discharge into streams. The BFI is the ratio of base flow to total flow, expressed as a percentage, within AOI | K21: TMIN9120WS | L21: =IF(RIGHT(K21,2)="WS", LEFT(K21,LEN(K21)-2),K21) -> TMIN9120 | M21: =INDEX(Active!J:J, MATCH(Spearmans2!L21, Active!F:F,0),1) -> 30-year Average Annual Normal Minimum Air Temperature | N21: =INDEX(Active!B:B, MATCH(Spearmans2!L21, Active!F:F,0),1) -> Natural | O21: =INDEX(Active!K:K, MATCH(Spearmans2!L21, Active!F:F,0),1) -> PRISM climate data - 30-year normal minimum temperature (CÂ°): Annual period: 1991-2020 within the AOI | P21: 30-year Average Annual Normal Minimum Air Temperature | Q21: Natural | R21: PRISM climate data - 30-year normal minimum temperature (CÂ°): Annual period: 1991-2020 within the AOI | S21: -0.83217987
A22: BFIWS | B22: =IF(RIGHT(A22,2)="WS", LEFT(A22,LEN(A22)-2),A22) -> BFI | C22: =INDEX(Active!J:J, MATCH(Spearmans2!B22, Active!F:F,0),1) -> Base Flow Index | D22: =INDEX(Active!B:B, MATCH(Spearmans2!B22, Active!F:F,0),1) -> Natural | E22: =INDEX(Active!D:D, MATCH(Spearmans2!B22, Active!F:F,0),1) -> Flow | F22: =INDEX(Active!K:K, MATCH(Spearmans2!B22, Active!F:F,0),1) -> Base flow is the component of streamflow that can be attributed to ground-water discharge into streams. The BFI is the ratio of base flow to total flow, expressed as a percentage, within AOI | G22: Base Flow Index | H22: Natural | I22: Flow | J22: Base flow is the component of streamflow that can be attributed to ground-water discharge into streams. The BFI is the ratio of base flow to total flow, expressed as a percentage, within AOI | K22: TMIN8110WS | L22: =IF(RIGHT(K22,2)="WS", LEFT(K22,LEN(K22)-2),K22) -> TMIN8110 | M22: =INDEX(Active!J:J, MATCH(Spearmans2!L22, Active!F:F,0),1) -> 30-year Average Annual Normal Minimum Air Temperature | N22: =INDEX(Active!B:B, MATCH(Spearmans2!L22, Active!F:F,0),1) -> Natural | O22: =INDEX(Active!K:K, MATCH(Spearmans2!L22, Active!F:F,0),1) -> PRISM climate data - 30-year normal minimum temperature (CÂ°): Annual period: 1981-2010 within the AOI | P22: 30-year Average Annual Normal Minimum Air Temperature | Q22: Natural | R22: PRISM climate data - 30-year normal minimum temperature (CÂ°): Annual period: 1981-2010 within the AOI | S22: -0.82646241
A23: BFIWS | B23: =IF(RIGHT(A23,2)="WS", LEFT(A23,LEN(A23)-2),A23) -> BFI | C23: =INDEX(Active!J:J, MATCH(Spearmans2!B23, Active!F:F,0),1) -> Base Flow Index | D23: =INDEX(Active!B:B, MATCH(Spearmans2!B23, Active!F:F,0),1) -> Natural | E23: =INDEX(Active!D:D, MATCH(Spearmans2!B23, Active!F:F,0),1) -> Flow | F23: =INDEX(Active!K:K, MATCH(Spearmans2!B23, Active!F:F,0),1) -> Base flow is the component of streamflow that can be attributed to ground-water discharge into streams. The BFI is the ratio of base flow to total flow, expressed as a percentage, within AOI | G23: Base Flow Index | H23: Natural | I23: Flow | J23: Base flow is the component of streamflow that can be attributed to ground-water discharge into streams. The BFI is the ratio of base flow to total flow, expressed as a percentage, within AOI | K23: TMEAN9120WS | L23: =IF(RIGHT(K23,2)="WS", LEFT(K23,LEN(K23)-2),K23) -> TMEAN9120 | M23: =INDEX(Active!J:J, MATCH(Spearmans2!L23, Active!F:F,0),1) -> 30-year Mean Annual Air Temperature | N23: =INDEX(Active!B:B, MATCH(Spearmans2!L23, Active!F:F,0),1) -> Natural | O23: =INDEX(Active!K:K, MATCH(Spearmans2!L23, Active!F:F,0),1) -> PRISM climate data - 30-year normal mean temperature (CÂ°): Annual period: 1991-2020 within the AOI | P23: 30-year Mean Annual Air Temperature | Q23: Natural | R23: PRISM climate data - 30-year normal mean temperature (CÂ°): Annual period: 1991-2020 within the AOI | S23: -0.82148539
A24: BFIWS | B24: =IF(RIGHT(A24,2)="WS", LEFT(A24,LEN(A24)-2),A24) -> BFI | C24: =INDEX(Active!J:J, MATCH(Spearmans2!B24, Active!F:F,0),1) -> Base Flow Index | D24: =INDEX(Active!B:B, MATCH(Spearmans2!B24, Active!F:F,0),1) -> Natural | E24: =INDEX(Active!D:D, MATCH(Spearmans2!B24, Active!F:F,0),1) -> Flow | F24: =INDEX(Active!K:K, MATCH(Spearmans2!B24, Active!F:F,0),1) -> Base flow is the component of streamflow that can be attributed to ground-water discharge into streams. The BFI is the ratio of base flow to total flow, expressed as a percentage, within AOI | G24: Base Flow Index | H24: Natural | I24: Flow | J24: Base flow is the component of streamflow that can be attributed to ground-water discharge into streams. The BFI is the ratio of base flow to total flow, expressed as a percentage, within AOI | K24: TMEAN8110WS | L24: =IF(RIGHT(K24,2)="WS", LEFT(K24,LEN(K24)-2),K24) -> TMEAN8110 | M24: =INDEX(Active!J:J, MATCH(Spearmans2!L24, Active!F:F,0),1) -> 30-year Mean Annual Air Temperature | N24: =INDEX(Active!B:B, MATCH(Spearmans2!L24, Active!F:F,0),1) -> Natural | O24: =INDEX(Active!K:K, MATCH(Spearmans2!L24, Active!F:F,0),1) -> PRISM climate data - 30-year normal mean temperature (CÂ°): Annual period: 1981-2010 within the AOI | P24: 30-year Mean Annual Air Temperature | Q24: Natural | R24: PRISM climate data - 30-year normal mean temperature (CÂ°): Annual period: 1981-2010 within the AOI | S24: -0.81877584
A25: BFIWS | B25: =IF(RIGHT(A25,2)="WS", LEFT(A25,LEN(A25)-2),A25) -> BFI | C25: =INDEX(Active!J:J, MATCH(Spearmans2!B25, Active!F:F,0),1) -> Base Flow Index | D25: =INDEX(Active!B:B, MATCH(Spearmans2!B25, Active!F:F,0),1) -> Natural | E25: =INDEX(Active!D:D, MATCH(Spearmans2!B25, Active!F:F,0),1) -> Flow | F25: =INDEX(Active!K:K, MATCH(Spearmans2!B25, Active!F:F,0),1) -> Base flow is the component of streamflow that can be attributed to ground-water discharge into streams. The BFI is the ratio of base flow to total flow, expressed as a percentage, within AOI | G25: Base Flow Index | H25: Natural | I25: Flow | J25: Base flow is the component of streamflow that can be attributed to ground-water discharge into streams. The BFI is the ratio of base flow to total flow, expressed as a percentage, within AOI | K25: TMEAN2008WS | L25: =IF(RIGHT(K25,2)="WS", LEFT(K25,LEN(K25)-2),K25) -> TMEAN2008 | M25: =INDEX(Active!J:J, MATCH(Spearmans2!L25, Active!F:F,0),1) -> Mean Air Temperature | N25: =INDEX(Active!B:B, MATCH(Spearmans2!L25, Active!F:F,0),1) -> Natural | O25: =INDEX(Active!K:K, MATCH(Spearmans2!L25, Active!F:F,0),1) -> PRISM climate data - Mean temperature (°C) within the AOI. Period: 2008 and 2009 | P25: Mean Air Temperature | Q25: Natural | R25: PRISM climate data - Mean temperature (°C) within the AOI. Period: 2008 and 2009 | S25: -0.80394435
A26: CAOWS | B26: =IF(RIGHT(A26,2)="WS", LEFT(A26,LEN(A26)-2),A26) -> CAO | C26: =INDEX(Active!J:J, MATCH(Spearmans2!B26, Active!F:F,0),1) -> Mean Lithological Calcium Oxide | D26: =INDEX(Active!B:B, MATCH(Spearmans2!B26, Active!F:F,0),1) -> Natural | E26: =INDEX(Active!D:D, MATCH(Spearmans2!B26, Active!F:F,0),1) -> Lithology | F26: =INDEX(Active!K:K, MATCH(Spearmans2!B26, Active!F:F,0),1) -> Mean % of lithological calcium oxide (CaO) content in surface or near surface geology within AOI | G26: Mean Lithological Calcium Oxide | H26: Natural | I26: Lithology | J26: Mean % of lithological calcium oxide (CaO) content in surface or near surface geology within AOI | K26: SIO2WS | L26: =IF(RIGHT(K26,2)="WS", LEFT(K26,LEN(K26)-2),K26) -> SIO2 | M26: =INDEX(Active!J:J, MATCH(Spearmans2!L26, Active!F:F,0),1) -> Mean Lithological Silicon Dioxide | N26: =INDEX(Active!B:B, MATCH(Spearmans2!L26, Active!F:F,0),1) -> Natural | O26: =INDEX(Active!K:K, MATCH(Spearmans2!L26, Active!F:F,0),1) -> Mean % of lithological silicon dioxide (SiO2) content in surface or near surface geology within AOI | P26: Mean Lithological Silicon Dioxide | Q26: Natural | R26: Mean % of lithological silicon dioxide (SiO2) content in surface or near surface geology within AOI | S26: -0.91125059
A27: CAOWS | B27: =IF(RIGHT(A27,2)="WS", LEFT(A27,LEN(A27)-2),A27) -> CAO | C27: =INDEX(Active!J:J, MATCH(Spearmans2!B27, Active!F:F,0),1) -> Mean Lithological Calcium Oxide | D27: =INDEX(Active!B:B, MATCH(Spearmans2!B27, Active!F:F,0),1) -> Natural | E27: =INDEX(Active!D:D, MATCH(Spearmans2!B27, Active!F:F,0),1) -> Lithology | F27: =INDEX(Active!K:K, MATCH(Spearmans2!B27, Active!F:F,0),1) -> Mean % of lithological calcium oxide (CaO) content in surface or near surface geology within AOI | G27: Mean Lithological Calcium Oxide | H27: Natural | I27: Lithology | J27: Mean % of lithological calcium oxide (CaO) content in surface or near surface geology within AOI | K27: AL2O3WS | L27: =IF(RIGHT(K27,2)="WS", LEFT(K27,LEN(K27)-2),K27) -> AL2O3 | M27: =INDEX(Active!J:J, MATCH(Spearmans2!L27, Active!F:F,0),1) -> Mean Lithological Aluminum Oxide | N27: =INDEX(Active!B:B, MATCH(Spearmans2!L27, Active!F:F,0),1) -> Natural | O27: =INDEX(Active!K:K, MATCH(Spearmans2!L27, Active!F:F,0),1) -> Mean % of lithological aluminum oxide (Al2O3) content in surface or near surface geology within AOI | P27: Mean Lithological Aluminum Oxide | Q27: Natural | R27: Mean % of lithological aluminum oxide (Al2O3) content in surface or near surface geology within AOI | S27: 0.82627092
A28: CAOWS | B28: =IF(RIGHT(A28,2)="WS", LEFT(A28,LEN(A28)-2),A28) -> CAO | C28: =INDEX(Active!J:J, MATCH(Spearmans2!B28, Active!F:F,0),1) -> Mean Lithological Calcium Oxide | D28: =INDEX(Active!B:B, MATCH(Spearmans2!B28, Active!F:F,0),1) -> Natural | E28: =INDEX(Active!D:D, MATCH(Spearmans2!B28, Active!F:F,0),1) -> Lithology | F28: =INDEX(Active!K:K, MATCH(Spearmans2!B28, Active!F:F,0),1) -> Mean % of lithological calcium oxide (CaO) content in surface or near surface geology within AOI | G28: Mean Lithological Calcium Oxide | H28: Natural | I28: Lithology | J28: Mean % of lithological calcium oxide (CaO) content in surface or near surface geology within AOI | K28: MGOWS | L28: =IF(RIGHT(K28,2)="WS", LEFT(K28,LEN(K28)-2),K28) -> MGO | M28: =INDEX(Active!J:J, MATCH(Spearmans2!L28, Active!F:F,0),1) -> Mean Lithological Magnesium Oxide | N28: =INDEX(Active!B:B, MATCH(Spearmans2!L28, Active!F:F,0),1) -> Natural | O28: =INDEX(Active!K:K, MATCH(Spearmans2!L28, Active!F:F,0),1) -> Mean % of lithological magnesium oxide (MgO) content in surface or near surface geology within AOI | P28: Mean Lithological Magnesium Oxide | Q28: Natural | R28: Mean % of lithological magnesium oxide (MgO) content in surface or near surface geology within AOI | S28: 0.88052675
A29: CAOWS | B29: =IF(RIGHT(A29,2)="WS", LEFT(A29,LEN(A29)-2),A29) -> CAO | C29: =INDEX(Active!J:J, MATCH(Spearmans2!B29, Active!F:F,0),1) -> Mean Lithological Calcium Oxide | D29: =INDEX(Active!B:B, MATCH(Spearmans2!B29, Active!F:F,0),1) -> Natural | E29: =INDEX(Active!D:D, MATCH(Spearmans2!B29, Active!F:F,0),1) -> Lithology | F29: =INDEX(Active!K:K, MATCH(Spearmans2!B29, Active!F:F,0),1) -> Mean % of lithological calcium oxide (CaO) content in surface or near surface geology within AOI | G29: Mean Lithological Calcium Oxide | H29: Natural | I29: Lithology | J29: Mean % of lithological calcium oxide (CaO) content in surface or near surface geology within AOI | K29: P2O5WS | L29: =IF(RIGHT(K29,2)="WS", LEFT(K29,LEN(K29)-2),K29) -> P2O5 | M29: =INDEX(Active!J:J, MATCH(Spearmans2!L29, Active!F:F,0),1) -> Mean Lithological Phosphorous Oxide | N29: =INDEX(Active!B:B, MATCH(Spearmans2!L29, Active!F:F,0),1) -> Natural | O29: =INDEX(Active!K:K, MATCH(Spearmans2!L29, Active!F:F,0),1) -> Mean % of lithological phosphorous oxide (P2O5) content in surface or near surface geology within AOI | P29: Mean Lithological Phosphorous Oxide | Q29: Natural | R29: Mean % of lithological phosphorous oxide (P2O5) content in surface or near surface geology within AOI | S29: 0.93815151
A30: CBNFWS | B30: =IF(RIGHT(A30,2)="WS", LEFT(A30,LEN(A30)-2),A30) -> CBNF | C30: =INDEX(Active!J:J, MATCH(Spearmans2!B30, Active!F:F,0),1) -> Cultivated Biological Nitrogen Fixation Mean Rate | D30: =INDEX(Active!B:B, MATCH(Spearmans2!B30, Active!F:F,0),1) -> Anthropogenic | E30: =INDEX(Active!D:D, MATCH(Spearmans2!B30, Active!F:F,0),1) -> Agriculture | F30: =INDEX(Active!K:K, MATCH(Spearmans2!B30, Active!F:F,0),1) -> Mean rate of biological nitrogen fixation from the cultivation of crops in kg N/ha/yr, within AOI | G30: Cultivated Biological Nitrogen Fixation Mean Rate | H30: Anthropogenic | I30: Agriculture | J30: Mean rate of biological nitrogen fixation from the cultivation of crops in kg N/ha/yr, within AOI | K30: MANUREWS | L30: =IF(RIGHT(K30,2)="WS", LEFT(K30,LEN(K30)-2),K30) -> MANURE | M30: =INDEX(Active!J:J, MATCH(Spearmans2!L30, Active!F:F,0),1) -> Mean Manure Application Rate | N30: =INDEX(Active!B:B, MATCH(Spearmans2!L30, Active!F:F,0),1) -> Anthropogenic | O30: =INDEX(Active!K:K, MATCH(Spearmans2!L30, Active!F:F,0),1) -> Mean rate of manure application to agricultural land from confined animal feeding operations in kg N/ha/yr, within AOI | P30: Mean Manure Application Rate | Q30: Anthropogenic | R30: Mean rate of manure application to agricultural land from confined animal feeding operations in kg N/ha/yr, within AOI | S30: 0.85548924
... A117: NANIWS | B117: =IF(RIGHT(A117,2)="WS", LEFT(A117,LEN(A117)-2),A117) -> NANI | C117: =INDEX(Active!J:J, MATCH(Spearmans2!B117, Active!F:F,0),1) -> Anthropogenic Nitrogen | D117: =INDEX(Active!B:B, MATCH(Spearmans2!B117, Active!F:F,0),1) -> Anthropogenic | E117: =INDEX(Active!D:D, MATCH(Spearmans2!B117, Active!F:F,0),1) -> Agriculture | F117: =INDEX(Active!K:K, MATCH(Spearmans2!B117, Active!F:F,0),1) -> Net Anthropogenic Nitrogen within AOI: farm fertilizer + urban fertilizer + NOx deposition + CBNF + Human and Livestock food - crop N content - livestock N content | G117: Anthropogenic Nitrogen | H117: Anthropogenic | I117: Agriculture | J117: Net Anthropogenic Nitrogen within AOI: farm fertilizer + urban fertilizer + NOx deposition + CBNF + Human and Livestock food - crop N content - livestock N content | K117: WETTEDWIDTH | L117: =IF(RIGHT(K117,2)="WS", LEFT(K117,LEN(K117)-2),K117) -> WETTEDWIDTH | M117: =INDEX(Active!J:J, MATCH(Spearmans2!L117, Active!F:F,0),1) -> Predicted Wetted Width | N117: =INDEX(Active!B:B, MATCH(Spearmans2!L117, Active!F:F,0),1) -> Natural | O117: =INDEX(Active!K:K, MATCH(Spearmans2!L117, Active!F:F,0),1) -> Predicted wetted width: distance of the waters edge from left to right bank | P117: Predicted Wetted Width | Q117: Natural | R117: Predicted wetted width: distance of the waters edge from left to right bank | S117: 0.84818722
A118: NANIWS | B118: =IF(RIGHT(A118,2)="WS", LEFT(A118,LEN(A118)-2),A118) -> NANI | C118: =INDEX(Active!J:J, MATCH(Spearmans2!B118, Active!F:F,0),1) -> Anthropogenic Nitrogen | D118: =INDEX(Active!B:B, MATCH(Spearmans2!B118, Active!F:F,0),1) -> Anthropogenic | E118: =INDEX(Active!D:D, MATCH(Spearmans2!B118, Active!F:F,0),1) -> Agriculture | F118: =INDEX(Active!K:K, MATCH(Spearmans2!B118, Active!F:F,0),1) -> Net Anthropogenic Nitrogen within AOI: farm fertilizer + urban fertilizer + NOx deposition + CBNF + Human and Livestock food - crop N content - livestock N content | G118: Anthropogenic Nitrogen | H118: Anthropogenic | I118: Agriculture | J118: Net Anthropogenic Nitrogen within AOI: farm fertilizer + urban fertilizer + NOx deposition + CBNF + Human and Livestock food - crop N content - livestock N content | K118: THALWEGDEPTH | L118: =IF(RIGHT(K118,2)="WS", LEFT(K118,LEN(K118)-2),K118) -> THALWEGDEPTH | M118: =INDEX(Active!J:J, MATCH(Spearmans2!L118, Active!F:F,0),1) -> #N/A | N118: =INDEX(Active!B:B, MATCH(Spearmans2!L118, Active!F:F,0),1) -> #N/A | O118: =INDEX(Active!K:K, MATCH(Spearmans2!L118, Active!F:F,0),1) -> #N/A | P118: #N/A | Q118: #N/A | R118: #N/A | S118: 0.88083328
A119: NANIWS | B119: =IF(RIGHT(A119,2)="WS", LEFT(A119,LEN(A119)-2),A119) -> NANI | C119: =INDEX(Active!J:J, MATCH(Spearmans2!B119, Active!F:F,0),1) -> Anthropogenic Nitrogen | D119: =INDEX(Active!B:B, MATCH(Spearmans2!B119, Active!F:F,0),1) -> Anthropogenic | E119: =INDEX(Active!D:D, MATCH(Spearmans2!B119, Active!F:F,0),1) -> Agriculture | F119: =INDEX(Active!K:K, MATCH(Spearmans2!B119, Active!F:F,0),1) -> Net Anthropogenic Nitrogen within AOI: farm fertilizer + urban fertilizer + NOx deposition + CBNF + Human and Livestock food - crop N content - livestock N content | G119: Anthropogenic Nitrogen | H119: Anthropogenic | I119: Agriculture | J119: Net Anthropogenic Nitrogen within AOI: farm fertilizer + urban fertilizer + NOx deposition + CBNF + Human and Livestock food - crop N content - livestock N content | K119: NSURPWS | L119: =IF(RIGHT(K119,2)="WS", LEFT(K119,LEN(K119)-2),K119) -> NSURP | M119: =INDEX(Active!J:J, MATCH(Spearmans2!L119, Active!F:F,0),1) -> Nitrogen Surplus | N119: =INDEX(Active!B:B, MATCH(Spearmans2!L119, Active!F:F,0),1) -> Anthropogenic | O119: =INDEX(Active!K:K, MATCH(Spearmans2!L119, Active!F:F,0),1) -> Nitrogen Surplus (kg N / yr) per AOI - excluding biological N Fixation | P119: Nitrogen Surplus | Q119: Anthropogenic | R119: Nitrogen Surplus (kg N / yr) per AOI - excluding biological N Fixation | S119: 0.99655683
A120: NH42008WS | B120: =IF(RIGHT(A120,2)="WS", LEFT(A120,LEN(A120)-2),A120) -> NH42008 | C120: =INDEX(Active!J:J, MATCH(Spearmans2!B120, Active!F:F,0),1) -> Mean annual Precipitation-Weighted NH4 Mean | D120: =INDEX(Active!B:B, MATCH(Spearmans2!B120, Active!F:F,0),1) -> Natural | E120: =INDEX(Active!D:D, MATCH(Spearmans2!B120, Active!F:F,0),1) -> Climate | F120: =INDEX(Active!K:K, MATCH(Spearmans2!B120, Active!F:F,0),1) -> Annual gradient map of precipitation-weighted mean deposition for ammonium ion concentration wet deposition for 2008 in kg of NH4/ha/yr, within AOI | G120: Mean annual Precipitation-Weighted NH4 Mean | H120: Natural | I120: Climate | J120: Annual gradient map of precipitation-weighted mean deposition for ammonium ion concentration wet deposition for 2008 in kg of NH4/ha/yr, within AOI | K120: PRECIP2008WS | L120: =IF(RIGHT(K120,2)="WS", LEFT(K120,LEN(K120)-2),K120) -> PRECIP2008 | M120: =INDEX(Active!J:J, MATCH(Spearmans2!L120, Active!F:F,0),1) -> Mean Precipitation | N120: =INDEX(Active!B:B, MATCH(Spearmans2!L120, Active!F:F,0),1) -> Natural | O120: =INDEX(Active!K:K, MATCH(Spearmans2!L120, Active!F:F,0),1) -> PRISM climate data - 30-year normal mean precipitation (mm): Annual period: 2008 and 2009 within the AOI | P120: Mean Precipitation | Q120: Natural | R120: PRISM climate data - 30-year normal mean precipitation (mm): Annual period: 2008 and 2009 within the AOI | S120: 0.82799086
A121: NH42008WS | B121: =IF(RIGHT(A121,2)="WS", LEFT(A121,LEN(A121)-2),A121) -> NH42008 | C121: =INDEX(Active!J:J, MATCH(Spearmans2!B121, Active!F:F,0),1) -> Mean annual Precipitation-Weighted NH4 Mean | D121: =INDEX(Active!B:B, MATCH(Spearmans2!B121, Active!F:F,0),1) -> Natural | E121: =INDEX(Active!D:D, MATCH(Spearmans2!B121, Active!F:F,0),1) -> Climate | F121: =INDEX(Active!K:K, MATCH(Spearmans2!B121, Active!F:F,0),1) -> Annual gradient map of precipitation-weighted mean deposition for ammonium ion concentration wet deposition for 2008 in kg of NH4/ha/yr, within AOI | G121: Mean annual Precipitation-Weighted NH4 Mean | H121: Natural | I121: Climate | J121: Annual gradient map of precipitation-weighted mean deposition for ammonium ion concentration wet deposition for 2008 in kg of NH4/ha/yr, within AOI | K121: PRECIP8110WS | L121: =IF(RIGHT(K121,2)="WS", LEFT(K121,LEN(K121)-2),K121) -> PRECIP8110 | M121: =INDEX(Active!J:J, MATCH(Spearmans2!L121, Active!F:F,0),1) -> 30-year Mean Annual Precipitation | N121: =INDEX(Active!B:B, MATCH(Spearmans2!L121, Active!F:F,0),1) -> Natural | O121: =INDEX(Active!K:K, MATCH(Spearmans2!L121, Active!F:F,0),1) -> PRISM climate data - 30-year normal mean precipitation (mm): Annual period: 1981-2010 within AOI | P121: 30-year Mean Annual Precipitation | Q121: Natural | R121: PRISM climate data - 30-year normal mean precipitation (mm): Annual period: 1981-2010 within AOI | S121: 0.84664382
A122: NH42008WS | B122: =IF(RIGHT(A122,2)="WS", LEFT(A122,LEN(A122)-2),A122) -> NH42008 | C122: =INDEX(Active!J:J, MATCH(Spearmans2!B122, Active!F:F,0),1) -> Mean annual Precipitation-Weighted NH4 Mean | D122: =INDEX(Active!B:B, MATCH(Spearmans2!B122, Active!F:F,0),1) -> Natural | E122: =INDEX(Active!D:D, MATCH(Spearmans2!B122, Active!F:F,0),1) -> Climate | F122: =INDEX(Active!K:K, MATCH(Spearmans2!B122, Active!F:F,0),1) -> Annual gradient map of precipitation-weighted mean deposition for ammonium ion concentration wet deposition for 2008 in kg of NH4/ha/yr, within AOI | G122: Mean annual Precipitation-Weighted NH4 Mean | H122: Natural | I122: Climate | J122: Annual gradient map of precipitation-weighted mean deposition for ammonium ion concentration wet deposition for 2008 in kg of NH4/ha/yr, within AOI | K122: PRECIP_MINUS_EVTWS | L122: =IF(RIGHT(K122,2)="WS", LEFT(K122,LEN(K122)-2),K122) -> PRECIP_MINUS_EVT | M122: =INDEX(Active!J:J, MATCH(Spearmans2!L122, Active!F:F,0),1) -> Surplus Precipitation | N122: =INDEX(Active!B:B, MATCH(Spearmans2!L122, Active!F:F,0),1) -> Natural | O122: =INDEX(Active!K:K, MATCH(Spearmans2!L122, Active!F:F,0),1) -> This dataset represents surplus precipitation (mm): precipitation minus potential evaporation described in DOI: 10.1016/j.scitotenv.2020.137661 within individual, local NHDPlusV2 catchments and upstream, contributing watersheds. | P122: Surplus Precipitation | Q122: Natural | R122: This dataset represents surplus precipitation (mm): precipitation minus potential evaporation described in DOI: 10.1016/j.scitotenv.2020.137661 within individual, local NHDPlusV2 catchments and upstream, contributing watersheds. | S122: 0.8479126
A123: NH42008WS | B123: =IF(RIGHT(A123,2)="WS", LEFT(A123,LEN(A123)-2),A123) -> NH42008 | C123: =INDEX(Active!J:J, MATCH(Spearmans2!B123, Active!F:F,0),1) -> Mean annual Precipitation-Weighted NH4 Mean | D123: =INDEX(Active!B:B, MATCH(Spearmans2!B123, Active!F:F,0),1) -> Natural | E123: =INDEX(Active!D:D, MATCH(Spearmans2!B123, Active!F:F,0),1) -> Climate | F123: =INDEX(Active!K:K, MATCH(Spearmans2!B123, Active!F:F,0),1) -> Annual gradient map of precipitation-weighted mean deposition for ammonium ion concentration wet deposition for 2008 in kg of NH4/ha/yr, within AOI | G123: Mean annual Precipitation-Weighted NH4 Mean | H123: Natural | I123: Climate | J123: Annual gradient map of precipitation-weighted mean deposition for ammonium ion concentration wet deposition for 2008 in kg of NH4/ha/yr, within AOI | K123: PRECIP9120WS | L123: =IF(RIGHT(K123,2)="WS", LEFT(K123,LEN(K123)-2),K123) -> PRECIP9120 | M123: =INDEX(Active!J:J, MATCH(Spearmans2!L123, Active!F:F,0),1) -> 30-year Mean Annual Precipitation | N123: =INDEX(Active!B:B, MATCH(Spearmans2!L123, Active!F:F,0),1) -> Natural | O123: =INDEX(Active!K:K, MATCH(Spearmans2!L123, Active!F:F,0),1) -> PRISM climate data - 30-year normal mean precipitation (mm): Annual period: 1991-2020 within the AOI | P123: 30-year Mean Annual Precipitation | Q123: Natural | R123: PRISM climate data - 30-year normal mean precipitation (mm): Annual period: 1991-2020 within the AOI | S123: 0.84792858
A124: NH42008WS | B124: =IF(RIGHT(A124,2)="WS", LEFT(A124,LEN(A124)-2),A124) -> NH42008 | C124: =INDEX(Active!J:J, MATCH(Spearmans2!B124, Active!F:F,0),1) -> Mean annual Precipitation-Weighted NH4 Mean | D124: =INDEX(Active!B:B, MATCH(Spearmans2!B124, Active!F:F,0),1) -> Natural | E124: =INDEX(Active!D:D, MATCH(Spearmans2!B124, Active!F:F,0),1) -> Climate | F124: =INDEX(Active!K:K, MATCH(Spearmans2!B124, Active!F:F,0),1) -> Annual gradient map of precipitation-weighted mean deposition for ammonium ion concentration wet deposition for 2008 in kg of NH4/ha/yr, within AOI | G124: Mean annual Precipitation-Weighted NH4 Mean | H124: Natural | I124: Climate | J124: Annual gradient map of precipitation-weighted mean deposition for ammonium ion concentration wet deposition for 2008 in kg of NH4/ha/yr, within AOI | K124: NO32008WS | L124: =IF(RIGHT(K124,2)="WS", LEFT(K124,LEN(K124)-2),K124) -> NO32008 | M124: =INDEX(Active!J:J, MATCH(Spearmans2!L124, Active!F:F,0),1) -> Mean Annual Precipitation-Weighted NO3 Mean | N124: =INDEX(Active!B:B, MATCH(Spearmans2!L124, Active!F:F,0),1) -> Natural | O124: =INDEX(Active!K:K, MATCH(Spearmans2!L124, Active!F:F,0),1) -> Annual gradient map of precipitation-weighted mean deposition for nitrate ion concentration wet deposition for 2008 in kg of NO3/ha/yr, within AOI | P124: Mean Annual Precipitation-Weighted NO3 Mean | Q124: Natural | R124: Annual gradient map of precipitation-weighted mean deposition for nitrate ion concentration wet deposition for 2008 in kg of NO3/ha/yr, within AOI | S124: 0.96267018
A125: NH42008WS | B125: =IF(RIGHT(A125,2)="WS", LEFT(A125,LEN(A125)-2),A125) -> NH42008 | C125: =INDEX(Active!J:J, MATCH(Spearmans2!B125, Active!F:F,0),1) -> Mean annual Precipitation-Weighted NH4 Mean | D125: =INDEX(Active!B:B, MATCH(Spearmans2!B125, Active!F:F,0),1) -> Natural | E125: =INDEX(Active!D:D, MATCH(Spearmans2!B125, Active!F:F,0),1) -> Climate | F125: =INDEX(Active!K:K, MATCH(Spearmans2!B125, Active!F:F,0),1) -> Annual gradient map of precipitation-weighted mean deposition for ammonium ion concentration wet deposition for 2008 in kg of NH4/ha/yr, within AOI | G125: Mean annual Precipitation-Weighted NH4 Mean | H125: Natural | I125: Climate | J125: Annual gradient map of precipitation-weighted mean deposition for ammonium ion concentration wet deposition for 2008 in kg of NH4/ha/yr, within AOI | K125: SN2008WS | L125: =IF(RIGHT(K125,2)="WS", LEFT(K125,LEN(K125)-2),K125) -> SN2008 | M125: =INDEX(Active!J:J, MATCH(Spearmans2!L125, Active!F:F,0),1) -> Annual Mean Sulfur and Nitrogen Wet Deposition | N125: =INDEX(Active!B:B, MATCH(Spearmans2!L125, Active!F:F,0),1) -> Natural | O125: =INDEX(Active!K:K, MATCH(Spearmans2!L125, Active!F:F,0),1) -> Annual gradient map of precipitation-weighted mean deposition for average sulfur & nitrogen wet deposition for 2008 in kg of S+N/ha/yr, within AOI | P125: Annual Mean Sulfur and Nitrogen Wet Deposition | Q125: Natural | R125: Annual gradient map of precipitation-weighted mean deposition for average sulfur & nitrogen wet deposition for 2008 in kg of S+N/ha/yr, within AOI | S125: 0.98088713
A126: NH42008WS | B126: =IF(RIGHT(A126,2)="WS", LEFT(A126,LEN(A126)-2),A126) -> NH42008 | C126: =INDEX(Active!J:J, MATCH(Spearmans2!B126, Active!F:F,0),1) -> Mean annual Precipitation-Weighted NH4 Mean | D126: =INDEX(Active!B:B, MATCH(Spearmans2!B126, Active!F:F,0),1) -> Natural | E126: =INDEX(Active!D:D, MATCH(Spearmans2!B126, Active!F:F,0),1) -> Climate | F126: =INDEX(Active!K:K, MATCH(Spearmans2!B126, Active!F:F,0),1) -> Annual gradient map of precipitation-weighted mean deposition for ammonium ion concentration wet deposition for 2008 in kg of NH4/ha/yr, within AOI | G126: Mean annual Precipitation-Weighted NH4 Mean | H126: Natural | I126: Climate | J126: Annual gradient map of precipitation-weighted mean deposition for ammonium ion concentration wet deposition for 2008 in kg of NH4/ha/yr, within AOI | K126: INORGNWETDEP2008WS | L126: =IF(RIGHT(K126,2)="WS", LEFT(K126,LEN(K126)-2),K126) -> INORGNWETDEP2008 | M126: =INDEX(Active!J:J, MATCH(Spearmans2!L126, Active!F:F,0),1) -> Mean Annual Precipitation-Weighted Nitrogen | N126: =INDEX(Active!B:B, MATCH(Spearmans2!L126, Active!F:F,0),1) -> Natural | O126: =INDEX(Active!K:K, MATCH(Spearmans2!L126, Active!F:F,0),1) -> Annual gradient map of precipitation-weighted mean deposition for inorganic nitrogen wet deposition from nitrate and ammonium for 2008 in kg of N/ha/yr, within AOI | P126: Mean Annual Precipitation-Weighted Nitrogen | Q126: Natural | R126: Annual gradient map of precipitation-weighted mean deposition for inorganic nitrogen wet deposition from nitrate and ammonium for 2008 in kg of N/ha/yr, within AOI | S126: 0.993802
...

Sheet Sheet1
A1: rowname
A2: AGKFFACTWS | E2: =CHAR(34)&_xlfn.TEXTJOIN(""",""", TRUE, A:A)&CHAR(34) -> "rowname","AGKFFACTWS","AL2O3WS","BANKFULLDEPTH","BANKFULLWIDTH","BFIWS","CAOWS","CBNFWS","CLAYWS","CONNWS","DAMDENSWS","DAMNIDSTORWS","DAMNRMSTORWS","ELEVWS","FE2O3WS","FERTWS","HABTWS","HUDEN2010WS","ICI","INORGNWETDEP2008WS","IWI","K2OWS","MANUREWS","MAST2008","MGOWS","MWST2008","NA2OWS","NABD_DENSWS","NABD_NIDSTORWS","NABD_NRMSTORWS","NANIWS","NH42008WS","NO32008WS","NSURPWS","P2O5WS","PCT_EROD","PCTAGSLPHIGH2001WS","PCTAGSLPMID2001WS","PCTBURNAREA2002WS","PCTDECID2001WS","PCTFIRE2002WS","PCTHAY2001WS","PCTHIGHSEV2002WS","PCTIMP2001WS","PCTIMPSLPHIGH2001WS","PCTIMPSLPMID2001WS","PCTLOWSEV2002WS","PCTMODSEV2002WS","PCTMXFST2001WS","PCTNONCARBRESIDWS","PCTSILICICWS","PCTUNDSEV2002WS","PCTURBLO2001WS","PCTURBMD2001WS","PERMWS","POPDEN2010WS","PRECIP_MINUS_EVTWS","PRECIP2008WS","PRECIP8110WS","PRECIP9120WS","RUNOFFWS","SANDWS","SEDWS","SIO2WS","SN2008WS","SW_FLUXWS","TEMPWS","THALWEGDEPTH","TMAX8110WS","TMAX9120WS","TMEAN2008WS","TMEAN8110WS","TMEAN9120WS","TMIN8110WS","TMIN9120WS","WATERINPUTWS","WDRW_LDWS","WETTEDWIDTH","WWTPALLDENSWS","WWTPMINORDENSWS"
A3: AL2O3WS | E3: "AGKFFACTWS","AL2O3WS","BANKFULLDEPTH","BANKFULLWIDTH","BFIWS","CAOWS","CBNFWS","CLAYWS","CONNWS","DAMDENSWS","DAMNIDSTORWS","DAMNRMSTORWS","ELEVWS","FE2O3WS","FERTWS","HABTWS","HUDEN2010WS","ICI","INORGNWETDEP2008WS","IWI","K2OWS","MANUREWS","MAST2008","MGOWS","MWST2008","NA2OWS","NABD_DENSWS","NABD_NIDSTORWS","NABD_NRMSTORWS","NANIWS","NH42008WS","NO32008WS","NSURPWS","P2O5WS","PCT_EROD","PCTAGSLPHIGH2001WS","PCTAGSLPMID2001WS","PCTBURNAREA2002WS","PCTDECID2001WS","PCTFIRE2002WS","PCTHAY2001WS","PCTHIGHSEV2002WS","PCTIMP2001WS","PCTIMPSLPHIGH2001WS","PCTIMPSLPMID2001WS","PCTLOWSEV2002WS","PCTMODSEV2002WS","PCTMXFST2001WS","PCTNONCARBRESIDWS","PCTSILICICWS","PCTUNDSEV2002WS","PCTURBLO2001WS","PCTURBMD2001WS","PERMWS","POPDEN2010WS","PRECIP_MINUS_EVTWS","PRECIP2008WS","PRECIP8110WS","PRECIP9120WS","RUNOFFWS","SANDWS","SEDWS","SIO2WS","SN2008WS","SW_FLUXWS","TEMPWS","THALWEGDEPTH","TMAX8110WS","TMAX9120WS","TMEAN2008WS","TMEAN8110WS","TMEAN9120WS","TMIN8110WS","TMIN9120WS","WATERINPUTWS","WDRW_LDWS","WETTEDWIDTH","WWTPALLDENSWS","WWTPMINORDENSWS"
A4: BANKFULLDEPTH
A5: BANKFULLWIDTH | E5: =_xlfn.TEXTJOIN(", ", TRUE, A:A) -> rowname, AGKFFACTWS, AL2O3WS, BANKFULLDEPTH, BANKFULLWIDTH, BFIWS, CAOWS, CBNFWS, CLAYWS, CONNWS, DAMDENSWS, DAMNIDSTORWS, DAMNRMSTORWS, ELEVWS, FE2O3WS, FERTWS, HABTWS, HUDEN2010WS, ICI, INORGNWETDEP2008WS, IWI, K2OWS, MANUREWS, MAST2008, MGOWS, MWST2008, NA2OWS, NABD_DENSWS, NABD_NIDSTORWS, NABD_NRMSTORWS, NANIWS, NH42008WS, NO32008WS, NSURPWS, P2O5WS, PCT_EROD, PCTAGSLPHIGH2001WS, PCTAGSLPMID2001WS, PCTBURNAREA2002WS, PCTDECID2001WS, PCTFIRE2002WS, PCTHAY2001WS, PCTHIGHSEV2002WS, PCTIMP2001WS, PCTIMPSLPHIGH2001WS, PCTIMPSLPMID2001WS, PCTLOWSEV2002WS, PCTMODSEV2002WS, PCTMXFST2001WS, PCTNONCARBRESIDWS, PCTSILICICWS, PCTUNDSEV2002WS, PCTURBLO2001WS, PCTURBMD2001WS, PERMWS, POPDEN2010WS, PRECIP_MINUS_EVTWS, PRECIP2008WS, PRECIP8110WS, PRECIP9120WS, RUNOFFWS, SANDWS, SEDWS, SIO2WS, SN2008WS, SW_FLUXWS, TEMPWS, THALWEGDEPTH, TMAX8110WS, TMAX9120WS, TMEAN2008WS, TMEAN8110WS, TMEAN9120WS, TMIN8110WS, TMIN9120WS, WATERINPUTWS, WDRW_LDWS, WETTEDWIDTH, WWTPALLDENSWS, WWTPMINORDENSWS
A6: BFIWS | E6: AGKFFACTWS, AL2O3WS, BANKFULLDEPTH, BANKFULLWIDTH, BFIWS, CAOWS, CBNFWS, CLAYWS, CONNWS, DAMDENSWS, DAMNIDSTORWS, DAMNRMSTORWS, ELEVWS, FE2O3WS, FERTWS, HABTWS, HUDEN2010WS, ICI, INORGNWETDEP2008WS, IWI, K2OWS, MANUREWS, MAST2008, MGOWS, MWST2008, NA2OWS, NABD_DENSWS, NABD_NIDSTORWS, NABD_NRMSTORWS, NANIWS, NH42008WS, NO32008WS, NSURPWS, P2O5WS, PCT_EROD, PCTAGSLPHIGH2001WS, PCTAGSLPMID2001WS, PCTBURNAREA2002WS, PCTDECID2001WS, PCTFIRE2002WS, PCTHAY2001WS, PCTHIGHSEV2002WS, PCTIMP2001WS, PCTIMPSLPHIGH2001WS, PCTIMPSLPMID2001WS, PCTLOWSEV2002WS, PCTMODSEV2002WS, PCTMXFST2001WS, PCTNONCARBRESIDWS, PCTSILICICWS, PCTUNDSEV2002WS, PCTURBLO2001WS, PCTURBMD2001WS, PERMWS, POPDEN2010WS, PRECIP_MINUS_EVTWS, PRECIP2008WS, PRECIP8110WS, PRECIP9120WS, RUNOFFWS, SANDWS, SEDWS, SIO2WS, SN2008WS, SW_FLUXWS, TEMPWS, THALWEGDEPTH, TMAX8110WS, TMAX9120WS, TMEAN2008WS, TMEAN8110WS, TMEAN9120WS, TMIN8110WS, TMIN9120WS, WATERINPUTWS, WDRW_LDWS, WETTEDWIDTH, WWTPALLDENSWS, WWTPMINORDENSWS
A7: CAOWS
A8: CBNFWS
A9: CLAYWS
A10: CONNWS
A11: DAMDENSWS
A12: DAMNIDSTORWS
A13: DAMNRMSTORWS
A14: ELEVWS
A15: FE2O3WS
A16: FERTWS
A17: HABTWS
A18: HUDEN2010WS
... A80: WWTPMINORDENSWS

Sheet Active
A1: Use? | B1: Category | C1: Subcategory_SC | D1: Subcategory | E1: Metric | F1: Metric_Query | G1: missing_from_pull | H1: AOI | I1: Year | J1: Short_Name | K1: Metric_Description | L1: Units | M1: Source | N1: Dataset
